Workbook

Sheet recibos
C1: FABRICA DE TABACOS GATO NEGRO “Gonzalo Jaimes Bastos” RIF. V-06676738-4
A2: FECHA: | C2: 20 DE MARZO DEL 2026 | J2: =+nombres!A1 -> F01 | K2: =+nombres!B1 -> ALCIDES CORREA | L2: =+nombres!C1 -> CC-88.193.514
A3: NOMBRE FABRIQUIN: | C3: =VLOOKUP(H3,nombres!A:C,2,0) -> JHONNY ALEXIS ALZATE NIÑO | F3: cedula | G3: =VLOOKUP(H3,nombres!A:C,3,0) -> CC-1.149.459.338 | H3: F64 | J3: =+nombres!A2 -> F03 | K3: =+nombres!B2 -> BLANCA ALVARADO | L3: =+nombres!C2 -> CC-60.402.510
A4: DESCRIPCION | B4: UNIDAD MEDIDA | C4: SALDO ANTERIOR | D4: CANTIDAD ENTREGADA | E4: RECIBIDA | F4: SALDO | G4: ENTREGADO POR | H4: RECIBIDO POR | J4: =+nombres!A3 -> F06 | K4: =+nombres!B3 -> ELVIRA LOPEZ | L4: =+nombres!C3 -> V-29.664.726
J5: =+nombres!A4 -> F07 | K5: =+nombres!B4 -> ERNESTO REYES | L5: =+nombres!C4 -> CC-5.535.335
A6: CAPA | B6: KG | C6: 0 | D6: 5 | J6: =+nombres!A5 -> F08 | K6: =+nombres!B5 -> GUILLERMO ZAMBRANO | L6: =+nombres!C5 -> V-5.642.663
A7: CAPOTE | B7: KG | C7: 0 | D7: 9 | J7: =+nombres!A6 -> F09 | K7: =+nombres!B6 -> HUGO ALMEIDA | L7: =+nombres!C6 -> V-8.998.550
A8: PICADURA | B8: KG | C8: 0 | D8: 35 | J8: =+nombres!A7 -> F10 | K8: =+nombres!B7 -> ILDA SERRANO | L8: =+nombres!C7 -> CC-60.413.802
A9: CESTAS | C9: 0 | D9: 4 | J9: =+nombres!A8 -> F11 | K9: =+nombres!B8 -> JOSE EBLAN GIRON | L9: =+nombres!C8 -> V-9.130.173
A10: SACAS | C10: 0 | J10: =+nombres!A9 -> F12 | K10: =+nombres!B9 -> JOSE JURADO | L10: =+nombres!C9 -> V-8986394
A11: GOMA | C11: 0 | J11: =+nombres!A10 -> F13 | K11: =+nombres!B10 -> LUZ MERY ABAUNZA | L11: =+nombres!C10 -> CC-60.407.054
A12: PERIODICO | B12: KG | C12: 0 | J12: =+nombres!A11 -> F15 | K12: =+nombres!B11 -> LUIS ROJAS | L12: =+nombres!C11 -> CC-79.336.610
A13: TRAPOS | C13: 0 | J13: =+nombres!A12 -> F16 | K13: =+nombres!B12 -> LUIS VALDERRAMA | L13: =+nombres!C12 -> V-23.095.033
A14: RESORTES | C14: 0 | J14: =+nombres!A13 -> F17 | K14: =+nombres!B13 -> LILIANA VEGA | L14: =+nombres!C13 -> V-11.021.605
A15: MAQ. ROLLERAS | C15: 0 | J15: =+nombres!A14 -> F22 | K15: =+nombres!B14 -> SULAY ALMEIDA | L15: =+nombres!C14 -> V-11.021.593
A16: PACORAS | C16: 0 | J16: =+nombres!A15 -> F23 | K16: =+nombres!B15 -> RUBIELA MARTINEZ | L16: =+nombres!C15 -> V-60.412.324
A17: CORTADORES | C17: 0 | J17: =+nombres!A16 -> F24 | K17: =+nombres!B16 -> ROSMIRA DURAN | L17: =+nombres!C16 -> CC-37.543.611
A18: CUCHILLAS | C18: 0 | J18: =+nombres!A17 -> F25 | K18: =+nombres!B17 -> ROSMIRA REY | L18: =+nombres!C17 -> V-23.165.190
A19: PRESTAMOS | C19: 0 | J19: =+nombres!A18 -> F26 | K19: =+nombres!B18 -> ROSALBA MATAGIRA | L19: =+nombres!C18 -> CC-37.221.293
A20: REZAGOS | C20: 0 | J20: =+nombres!A19 -> F27 | K20: =+nombres!B19 -> ROSA CORREA | L20: =+nombres!C19 -> V-15.856.304
J21: =+nombres!A20 -> F28 | K21: =+nombres!B20 -> LUZ ESTELA REYES SILVA | L21: =+nombres!C20 -> V-11.021.592
C22: FABRICA DE TABACOS GATO NEGRO “Gonzalo Jaimes Bastos” RIF. V-06676738-4 | J22: =+nombres!A21 -> F29 | K22: =+nombres!B21 -> TERESA REYES | L22: =+nombres!C21 -> V-27.893.136
A23: FECHA: | C23: =C2 -> 20 DE MARZO DEL 2026 | J23: =+nombres!A22 -> F30 | K23: =+nombres!B22 -> SAMUEL BERMUDEZ | L23: =+nombres!C22 -> V
A24: NOMBRE FABRIQUIN: | C24: =C3 -> JHONNY ALEXIS ALZATE NIÑO | F24: cedula | G24: =G3 -> CC-1.149.459.338 | H24: =H3 -> F64 | J24: =+nombres!A23 -> F31 | K24: =+nombres!B23 -> YARIRE ROA | L24: =+nombres!C23 -> V-14.975.665
A25: DESCRIPCION | B25: UNIDAD MEDIDA | C25: SALDO ANTERIOR | D25: CANTIDAD ENTREGADA | E25: RECIBIDA | F25: SALDO | G25: ENTREGADO POR | H25: RECIBIDO POR | J25: =+nombres!A24 -> F33 | K25: =+nombres!B24 -> YOLI BECERRA | L25: =+nombres!C24 -> V-11.017.442
J26: =+nombres!A25 -> F34 | K26: =+nombres!B25 -> GLORIA RODRIGUEZ | L26: =+nombres!C25 -> V-29.515.312
A27: CAPA | B27: =+B6 -> KG | C27: =+C6 -> 0 | D27: =+D6 -> 5 | J27: =+nombres!A26 -> F35 | K27: =+nombres!B26 -> LUIS ERNESTO ALMEIDA MANTILLA | L27: =+nombres!C26 -> V-13.365.579
A28: CAPOTE | B28: =+B7 -> KG | C28: =+C7 -> 0 | D28: =+D7 -> 9 | J28: =+nombres!A27 -> F36 | K28: =+nombres!B27 -> RENE HAMILTON GOMEZ ALMEIDA | L28: =+nombres!C27 -> V-21.033.815
A29: PICADURA | B29: =+B8 -> KG | C29: =+C8 -> 0 | D29: =+D8 -> 35 | J29: =+nombres!A28 -> F37 | K29: =+nombres!B28 -> MAYERLIN BOLIVAR CAMARGO | L29: =+nombres!C28 -> V-15.774.803
A30: CESTAS | B30: =+B9 -> 0 | C30: =+C9 -> 0 | D30: =+D9 -> 4 | J30: =+nombres!A29 -> F40 | K30: =+nombres!B29 -> RAMON PARRA | L30: =+nombres!C29 -> V-5.327.891
A31: SACAS | C31: =+C10 -> 0 | D31: =+D10 -> 0 | J31: =+nombres!A30 -> F43 | K31: =+nombres!B30 -> ELIZABET REYES | L31: =+nombres!C30 -> V-15.956.387
A32: GOMA | C32: =+C11 -> 0 | D32: =+D11 -> 0 | J32: =+nombres!A31 -> F46 | K32: =+nombres!B31 -> KARINA RINCON SILVA | L32: =+nombres!C31 -> V-17.465.799
A33: PERIODICO | B33: KG | C33: =+C12 -> 0 | D33: =+D12 -> 0 | J33: =+nombres!A32 -> F47 | K33: =+nombres!B32 -> HUMBERTO LUNA | L33: =+nombres!C32 -> V-25.344.223
A34: TRAPOS | C34: =+C13 -> 0 | D34: =+D13 -> 0 | J34: =+nombres!A33 -> F48 | K34: =+nombres!B33 -> MARIA MEDINA | L34: =+nombres!C33 -> V-22.680.548
A35: RESORTES | C35: =+C14 -> 0 | D35: =+D14 -> 0 | J35: =+nombres!A34 -> F49 | K35: =+nombres!B34 -> PEDRO ALCIRA | L35: =+nombres!C34 -> V-25.955.714
A36: MAQ. ROLLERAS | C36: =+C15 -> 0 | D36: =+D15 -> 0 | J36: =+nombres!A35 -> F50 | K36: =+nombres!B35 -> ESPERANZA REY | L36: =+nombres!C35 -> V-22.633.248
A37: PACORAS | C37: =+C16 -> 0 | D37: =+D16 -> 0 | J37: =+nombres!A36 -> F44 | K37: =+nombres!B36 -> MARIA ELENA CORREA | L37: =+nombres!C36 -> CC-84.395.969
A38: CORTADORES | C38: =+C17 -> 0 | D38: =+D17 -> 0 | J38: =+nombres!A37 -> F51 | K38: =+nombres!B37 -> RAUL REYES | L38: =+nombres!C37 -> V-11.718.244
A39: CUCHILLAS | C39: =+C18 -> 0 | D39: =+D18 -> 0 | J39: =+nombres!A38 -> F52 | K39: =+nombres!B38 -> LEYDI SERRANO | L39: =+nombres!C38 -> V-15.958.666
A40: PRESTAMOS | C40: =+C19 -> 0 | D40: =+D19 -> 0 | J40: =+nombres!A39 -> F53 | K40: =+nombres!B39 -> PETTER BENAVIDES | L40: =+nombres!C39 -> V-8.991.028
...

Sheet nombres
A1: F01 | B1: ALCIDES CORREA | C1: CC-88.193.514
A2: F03 | B2: BLANCA ALVARADO | C2: CC-60.402.510
A3: F06 | B3: ELVIRA LOPEZ | C3: V-29.664.726
A4: F07 | B4: ERNESTO REYES | C4: CC-5.535.335
A5: F08 | B5: GUILLERMO ZAMBRANO | C5: V-5.642.663
A6: F09 | B6: HUGO ALMEIDA | C6: V-8.998.550
A7: F10 | B7: ILDA SERRANO | C7: CC-60.413.802
A8: F11 | B8: JOSE EBLAN GIRON | C8: V-9.130.173
A9: F12 | B9: JOSE JURADO | C9: V-8986394
A10: F13 | B10: LUZ MERY ABAUNZA | C10: CC-60.407.054
A11: F15 | B11: LUIS ROJAS | C11: CC-79.336.610
A12: F16 | B12: LUIS VALDERRAMA | C12: V-23.095.033
... A48: F64 | B48: JHONNY ALEXIS ALZATE NIÑO | C48: CC-1.149.459.338

Sheet ESTABILIZANTE 
A1: ESTABILIZANTE 63 PAQUETES | F1: ESTABILIZANTE 63 PAQUETES
A2: FECHA | B2: NOMBRE FABRIQUIN | C2: NUMERO | F2: FECHA | G2: NOMBRE FABRIQUIN | H2: NUMERO
A3: 45680 | B3: LUIS ROJAS | C3: 1 | F3: 45992 | G3: JOSE JURADO | H3: 1
A4: 45680 | B4: ALCIDES CORREA | C4: =+C3+1 -> 2 | F4: 45999 | G4: LUIS ROJAS | H4: =+H3+1 -> 2
A5: 45682 | B5: SAMUEL BERMUDEZ | C5: =+C4+1 -> 3 | F5: 46001 | G5: ALCIDES | H5: =+H4+1 -> 3
A6: 45838 | B6: MAYERLIN BOLIVAR | C6: =+C5+1 -> 4 | F6: 46001 | G6: MAYERLIN BOLIVAR | H6: =+H5+1 -> 4
A7: 45842 | B7: JOSE JURADO | C7: =+C6+1 -> 5 | F7: 46035 | G7: FABRICA | H7: =+H6+1 -> 5
A8: 45845 | B8: LUIS ALMEIDA | C8: =+C7+1 -> 6 | H8: =+H7+1 -> 6
A9: 45845 | B9: ELVIRA LOPEZ | C9: =+C8+1 -> 7 | H9: =+H8+1 -> 7
A10: 45846 | B10: LUIS ROJAS | C10: =+C9+1 -> 8 | H10: =+H9+1 -> 8
A11: 45864 | B11: LUIS ROJAS | C11: =+C10+1 -> 9 | H11: =+H10+1 -> 9
A12: 45864 | B12: SAMUEL BERMUDEZ | C12: =+C11+1 -> 10 | H12: =+H11+1 -> 10
A13: 45864 | B13: RENE ALMEIDA | C13: =+C12+1 -> 11 | H13: =+H12+1 -> 11
A14: 45864 | B14: MAYERLIN BOLIVAR | C14: =+C13+1 -> 12 | H14: =+H13+1 -> 12
A15: 45871 | B15: JOSE EBLAN | C15: =+C14+1 -> 13 | H15: =+H14+1 -> 13
A16: 45871 | B16: ELVIRA LOPEZ | C16: =+C15+1 -> 14 | H16: =+H15+1 -> 14
A17: 45871 | B17: HUMBERTO LUNA | C17: =+C16+1 -> 15 | H17: =+H16+1 -> 15
A18: 45871 | B18: ERNESTO REYES | C18: =+C17+1 -> 16 | H18: =+H17+1 -> 16
A19: 45878 | B19: ELVIRA LOPEZ | C19: =+C18+1 -> 17 | H19: =+H18+1 -> 17
... A24: 45892 | B24: HUMBERTO LUNA | C24: =+C23+1 -> 22 | H24: =+H23+1 -> 22
C25: =+C24+1 -> 23 | H25: =+H24+1 -> 23
A26: 45895 | B26: JOSE JURADO | C26: =+C25+1 -> 24 | H26: =+H25+1 -> 24
A27: 45900 | B27: RENE ALMEIDA | C27: =+C26+1 -> 25 | H27: =+H26+1 -> 25
A28: 45900 | B28: LUIS ROJAS | C28: =+C27+1 -> 26 | H28: =+H27+1 -> 26
A29: 45908 | B29: SAMUEL BERMUDEZ | C29: =+C28+1 -> 27 | H29: =+H28+1 -> 27
A30: 45908 | B30: MAYERLIN BOLIVAR | C30: =+C29+1 -> 28 | H30: =+H29+1 -> 28
A31: 45908 | B31: ALCIDES CORREA | C31: =+C30+1 -> 29 | H31: =+H30+1 -> 29
A32: 45908 | B32: SULAY ALMEIDA | C32: =+C31+1 -> 30 | H32: =+H31+1 -> 30
A33: 45915 | B33: JOSE ABLAN GIRON | C33: =+C32+1 -> 31 | H33: =+H32+1 -> 31
A34: 45915 | B34: HUMBERTO LUNA | C34: =+C33+1 -> 32 | H34: =+H33+1 -> 32
A35: 45923 | B35: RENE ALMEIDA | C35: =+C34+1 -> 33 | H35: =+H34+1 -> 33
A36: 45923 | B36: MAYERLIN BOLIVAR | C36: =+C35+1 -> 34 | H36: =+H35+1 -> 34
A37: 45923 | B37: LUIS ROJAS | C37: =+C36+1 -> 35 | H37: =+H36+1 -> 35
... A58: 45962 | B58: LUIS ROJAS | C58: =+C57+1 -> 56 | H58: =+H57+1 -> 56
A59: 45962 | C59: =+C58+1 -> 57 | H59: =+H58+1 -> 57
A60: 45962 | B60: LUIS ERNESTO ALMEIDA | C60: =+C59+1 -> 58 | H60: =+H59+1 -> 58
A61: 45969 | B61: JOSE EBLAN | C61: =+C60+1 -> 59 | H61: =+H60+1 -> 59
A62: 45978 | B62: LUIS ROJAS | C62: =+C61+1 -> 60 | H62: =+H61+1 -> 60
A63: 45985 | B63: HUMBERTO LUNA | C63: =+C62+1 -> 61 | H63: =+H62+1 -> 61
A64: 45985 | B64: RENE ALMEIDA | C64: =+C63+1 -> 62 | H64: =+H63+1 -> 62
...
