Workbook

Sheet CONTROL DE RAZAGOS
B1: CONTROL DE REZAGOS | E1: DEL | H1: al | K1: OBSERVACIONES
A3: CODIGO | B3: NOMBRE Y APELLIDO | C3: CODIGO | D3: LUNES | E3: MARTES | F3: MIERCOLES | G3: JUEVES | H3: VIERNES | I3: SABADO | J3: TOTAL
A4: 1 | B4: =+'SEMANA DEL 2 AL 7-3-26'!A5 -> ALCIDES CORREA | C4: AC
A5: =+A4+1 -> 2 | B5: =+'SEMANA DEL 2 AL 7-3-26'!A7 -> BLANCA ALVARADO | C5: BNA
A6: =+A5+1 -> 3 | B6: =+'SEMANA DEL 2 AL 7-3-26'!A8 -> ESPERANZA REY | C6: E.R
A7: =+A6+1 -> 4 | B7: =+'SEMANA DEL 2 AL 7-3-26'!A9 -> ELIZABETH REYES SERRANO | C7: E.R.S
A8: =+A7+1 -> 5 | B8: =+'SEMANA DEL 2 AL 7-3-26'!A10 -> ELVIRA LOPEZ | C8: E.L
A9: =+A8+1 -> 6 | B9: =+'SEMANA DEL 2 AL 7-3-26'!A11 -> ERNESTO REYES | C9: E.REYES
A10: =+A9+1 -> 7 | B10: =+'SEMANA DEL 2 AL 7-3-26'!A12 -> GUILLERMO ZAMBRANO | C10: G.Z
A11: =+A10+1 -> 8 | B11: =+'SEMANA DEL 2 AL 7-3-26'!#REF! -> #REF! | C11: G.R
A12: =+A11+1 -> 9 | B12: =+'SEMANA DEL 2 AL 7-3-26'!A13 -> HUGO ALMEIDA | C12: H.A
A13: =+A12+1 -> 10 | B13: =+'SEMANA DEL 2 AL 7-3-26'!A14 -> HILDA SERRANO | C13: H.S
A14: =+A13+1 -> 11 | B14: =+'SEMANA DEL 2 AL 7-3-26'!A15 -> HUMBERTO LUNA | C14: H.L
A15: =+A14+1 -> 12 | B15: =+'SEMANA DEL 2 AL 7-3-26'!A16 -> JOSE EBLAN GIRON | C15: J.E.G
A16: =+A15+1 -> 13 | B16: =+'SEMANA DEL 2 AL 7-3-26'!A17 -> JOSE JURADO | C16: J,J
A17: =+A16+1 -> 14 | B17: =+'SEMANA DEL 2 AL 7-3-26'!A18 -> KARINA SILVA | C17: K.S
A18: =+A17+1 -> 15 | B18: =+'SEMANA DEL 2 AL 7-3-26'!A19 -> LUZ MERY ABAUNZA | C18: L.M.A
A19: =+A18+1 -> 16 | B19: =+'SEMANA DEL 2 AL 7-3-26'!A20 -> LUIS ROJAS | C19: L,R
A20: =+A19+1 -> 17 | B20: =+'SEMANA DEL 2 AL 7-3-26'!A21 -> LUIS VALDERRAMA | C20: L.V.C
A21: =+A20+1 -> 18 | B21: =+'SEMANA DEL 2 AL 7-3-26'!A22 -> LILIANA VEGA | C21: L,V
A22: =+A21+1 -> 19 | B22: =+'SEMANA DEL 2 AL 7-3-26'!A23 -> LUIS ERNESTO ALMEIDA | C22: L.E.A
A23: =+A22+1 -> 20 | B23: =+'SEMANA DEL 2 AL 7-3-26'!A24 -> LEIDY SERRANO | C23: L.S.S
... A25: =+A24+1 -> 22 | B25: =+'SEMANA DEL 2 AL 7-3-26'!A26 -> MARTHA SILVA | C25: M.S.
A26: =+A25+1 -> 23 | B26: =+'SEMANA DEL 2 AL 7-3-26'!A29 -> MARIA MEDINA | C26: M.M.
A27: =+A26+1 -> 24 | B27: =+'SEMANA DEL 2 AL 7-3-26'!#REF! -> #REF! | C27: M.E.C
A28: =+A27+1 -> 25 | B28: =+'SEMANA DEL 2 AL 7-3-26'!#REF! -> #REF! | C28: P.A
A29: =+A28+1 -> 26 | B29: =+'SEMANA DEL 2 AL 7-3-26'!A30 -> PETTER BENAVIDES | C29: P.B
A30: =+A29+1 -> 27 | B30: =+'SEMANA DEL 2 AL 7-3-26'!A31 -> RAMON PARRA | C30: R.P
A31: =+A30+1 -> 28 | B31: =+'SEMANA DEL 2 AL 7-3-26'!A32 -> SULAY ALMEIDA | C31: S.A
A32: =+A31+1 -> 29 | B32: =+'SEMANA DEL 2 AL 7-3-26'!#REF! -> #REF! | C32: R.A
A33: =+A32+1 -> 30 | B33: =+'SEMANA DEL 2 AL 7-3-26'!A33 -> RENE ALMEIDA | C33: H.R.A
A34: =+A33+1 -> 31 | B34: =+'SEMANA DEL 2 AL 7-3-26'!A34 -> RUBIELA MARTINEZ | C34: R.M.D
A35: =+A34+1 -> 32 | B35: =+'SEMANA DEL 2 AL 7-3-26'!A35 -> ROSMIRA DURAN | C35: R.D.
A36: =+A35+1 -> 33 | B36: =+'SEMANA DEL 2 AL 7-3-26'!#REF! -> #REF! | C36: R.R.
A37: =+A36+1 -> 34 | B37: =+'SEMANA DEL 2 AL 7-3-26'!A36 -> ROSALBA MATAGIRA | C37: R.M.
A38: =+A37+1 -> 35 | B38: =+'SEMANA DEL 2 AL 7-3-26'!#REF! -> #REF! | C38: R.C
A39: =+A38+1 -> 36 | B39: =+'SEMANA DEL 2 AL 7-3-26'!A37 -> STELLA SILVA | C39: S.SILVA
A40: =+A39+1 -> 37 | B40: =+'SEMANA DEL 2 AL 7-3-26'!#REF! -> #REF! | C40: A.S
A41: =+A40+1 -> 38 | B41: =+'SEMANA DEL 2 AL 7-3-26'!#REF! -> #REF! | C41: T.R
A42: =+A41+1 -> 39 | B42: =+'SEMANA DEL 2 AL 7-3-26'!A40 -> YENDER PADILLA | C42: Y.P
...

Sheet CONTROL DE CALIDAD 
A1: CONTROL DE REZAGOS
A3: ENCINTADOS
A4: CORTOS LA MEDIDA
A5: ROTOS
A6: DESCONADOS
A7: PERILLAS MALAS
A8: TABACO TRIPUDO

Sheet ENTREGA CESTAS 
E1: DEL | H1: al
A3: CODIGO | B3: NOMBRE Y APELLIDO | C3: CODIGO | D3: LUNES | E3: MARTES | F3: MIERCOLES | G3: JUEVES | H3: VIERNES | I3: SABADO | J3: TOTAL
A4: 1 | B4: =+'SEMANA DEL 2 AL 7-3-26'!A5 -> ALCIDES CORREA
A5: =+A4+1 -> 2 | B5: =+'SEMANA DEL 2 AL 7-3-26'!A6 -> ALBA SANABRIA
A6: =+A5+1 -> 3 | B6: =+'SEMANA DEL 2 AL 7-3-26'!A7 -> BLANCA ALVARADO
A7: =+A6+1 -> 4 | B7: =+'SEMANA DEL 2 AL 7-3-26'!A8 -> ESPERANZA REY
A8: =+A7+1 -> 5 | B8: =+'SEMANA DEL 2 AL 7-3-26'!A9 -> ELIZABETH REYES SERRANO
A9: =+A8+1 -> 6 | B9: =+'SEMANA DEL 2 AL 7-3-26'!A10 -> ELVIRA LOPEZ
A10: =+A9+1 -> 7 | B10: =+'SEMANA DEL 2 AL 7-3-26'!A11 -> ERNESTO REYES
A11: =+A10+1 -> 8 | B11: =+'SEMANA DEL 2 AL 7-3-26'!A12 -> GUILLERMO ZAMBRANO
A12: =+A11+1 -> 9 | B12: =+'SEMANA DEL 2 AL 7-3-26'!A13 -> HUGO ALMEIDA
A13: =+A12+1 -> 10 | B13: =+'SEMANA DEL 2 AL 7-3-26'!A14 -> HILDA SERRANO
A14: =+A13+1 -> 11 | B14: =+'SEMANA DEL 2 AL 7-3-26'!A15 -> HUMBERTO LUNA
A15: =+A14+1 -> 12 | B15: =+'SEMANA DEL 2 AL 7-3-26'!A16 -> JOSE EBLAN GIRON
A16: =+A15+1 -> 13 | B16: =+'SEMANA DEL 2 AL 7-3-26'!A17 -> JOSE JURADO
... A49: =+A48+1 -> 46 | B49: =+'SEMANA DEL 2 AL 7-3-26'!A50 -> 0
A50: =+A49+1 -> 47 | B50: =+'SEMANA DEL 2 AL 7-3-26'!A54 -> 0

Sheet ENTREGA MATERIAL 
D1: FECHA
A2: No | B2: NOMBRE | C2: CAPA | D2: CAPOTE | E2: PICADURA | F2: CESTAS
A3: 1 | B3: =+'SEMANA DEL 2 AL 7-3-26'!A5 -> ALCIDES CORREA
A4: =+A3+1 -> 2 | B4: =+'SEMANA DEL 2 AL 7-3-26'!A6 -> ALBA SANABRIA
A5: =+A4+1 -> 3 | B5: =+'SEMANA DEL 2 AL 7-3-26'!A7 -> BLANCA ALVARADO
A6: =+A5+1 -> 4 | B6: =+'SEMANA DEL 2 AL 7-3-26'!A8 -> ESPERANZA REY
A7: =+A6+1 -> 5 | B7: =+'SEMANA DEL 2 AL 7-3-26'!A9 -> ELIZABETH REYES SERRANO
A8: =+A7+1 -> 6 | B8: =+'SEMANA DEL 2 AL 7-3-26'!A10 -> ELVIRA LOPEZ
A9: =+A8+1 -> 7 | B9: =+'SEMANA DEL 2 AL 7-3-26'!A11 -> ERNESTO REYES
A10: =+A9+1 -> 8 | B10: =+'SEMANA DEL 2 AL 7-3-26'!A12 -> GUILLERMO ZAMBRANO
A11: =+A10+1 -> 9 | B11: =+'SEMANA DEL 2 AL 7-3-26'!A13 -> HUGO ALMEIDA
A12: =+A11+1 -> 10 | B12: =+'SEMANA DEL 2 AL 7-3-26'!A14 -> HILDA SERRANO
A13: =+A12+1 -> 11 | B13: =+'SEMANA DEL 2 AL 7-3-26'!A15 -> HUMBERTO LUNA
A14: =+A13+1 -> 12 | B14: =+'SEMANA DEL 2 AL 7-3-26'!A16 -> JOSE EBLAN GIRON
A15: =+A14+1 -> 13 | B15: =+'SEMANA DEL 2 AL 7-3-26'!A17 -> JOSE JURADO
... A45: =+A44+1 -> 43 | B45: =+'SEMANA DEL 2 AL 7-3-26'!A47 -> 0
A46: =+A45+1 -> 44 | B46: =+'SEMANA DEL 2 AL 7-3-26'!A51 -> 0
A47: =+A46+1 -> 45 | B47: =+'SEMANA DEL 2 AL 7-3-26'!A52 -> 0
A48: =+A47+1 -> 46 | B48: =+'SEMANA DEL 2 AL 7-3-26'!A53 -> 0
A49: =+A48+1 -> 47 | B49: =+'SEMANA DEL 2 AL 7-3-26'!A54 -> 0
B50: =+'SEMANA DEL 2 AL 7-3-26'!A55 -> 0

Sheet RECP-TAB-FAB
A1: RECEPCION DE CESTAS DE TABACOS FABRIQUINES | H1: al | J1: 2023
E2: LLEVAN | J2: TRAEN
A3: CODIGO | B3: NOMBRE Y APELLIDO | C3: CODIGO | D3: AMARILLAS | E3: AZULES | F3: ROJAS | G3: NEGRAS | H3: TOTAL | I3: AMARILLAS | J3: AZULES | K3: ROJAS | L3: NEGRAS | M3: TOTAL
A4: 1 | B4: =+'SEMANA DEL 2 AL 7-3-26'!A5 -> ALCIDES CORREA
A5: =+A4+1 -> 2 | B5: =+'SEMANA DEL 2 AL 7-3-26'!A7 -> BLANCA ALVARADO
A6: =+A5+1 -> 3 | B6: =+'SEMANA DEL 2 AL 7-3-26'!#REF! -> #REF!
A7: =+A6+1 -> 4 | B7: =+'SEMANA DEL 2 AL 7-3-26'!#REF! -> #REF!
A8: =+A7+1 -> 5 | B8: =+'SEMANA DEL 2 AL 7-3-26'!#REF! -> #REF!
A9: =+A8+1 -> 6 | B9: =+'SEMANA DEL 2 AL 7-3-26'!A9 -> ELIZABETH REYES SERRANO
A10: =+A9+1 -> 7 | B10: =+'SEMANA DEL 2 AL 7-3-26'!A10 -> ELVIRA LOPEZ
A11: =+A10+1 -> 8 | B11: =+'SEMANA DEL 2 AL 7-3-26'!A11 -> ERNESTO REYES
A12: =+A11+1 -> 9 | B12: =+'SEMANA DEL 2 AL 7-3-26'!A12 -> GUILLERMO ZAMBRANO
A13: =+A12+1 -> 10 | B13: =+'SEMANA DEL 2 AL 7-3-26'!#REF! -> #REF!
A14: =+A13+1 -> 11 | B14: =+'SEMANA DEL 2 AL 7-3-26'!A13 -> HUGO ALMEIDA
A15: =+A14+1 -> 12 | B15: =+'SEMANA DEL 2 AL 7-3-26'!A14 -> HILDA SERRANO
A16: =+A15+1 -> 13 | B16: =+'SEMANA DEL 2 AL 7-3-26'!A15 -> HUMBERTO LUNA
A17: =+A16+1 -> 14 | B17: =+'SEMANA DEL 2 AL 7-3-26'!A16 -> JOSE EBLAN GIRON
A18: =+A17+1 -> 15 | B18: =+'SEMANA DEL 2 AL 7-3-26'!A17 -> JOSE JURADO
A19: =+A18+1 -> 16 | B19: =+'SEMANA DEL 2 AL 7-3-26'!A18 -> KARINA SILVA
A20: =+A19+1 -> 17 | B20: =+'SEMANA DEL 2 AL 7-3-26'!A19 -> LUZ MERY ABAUNZA
A21: =+A20+1 -> 18 | B21: =+'SEMANA DEL 2 AL 7-3-26'!A20 -> LUIS ROJAS
A22: =+A21+1 -> 19 | B22: =+'SEMANA DEL 2 AL 7-3-26'!A21 -> LUIS VALDERRAMA
A23: =+A22+1 -> 20 | B23: =+'SEMANA DEL 2 AL 7-3-26'!A22 -> LILIANA VEGA
A24: =+A23+1 -> 21 | B24: =+'SEMANA DEL 2 AL 7-3-26'!A23 -> LUIS ERNESTO ALMEIDA
A25: =+A24+1 -> 22 | B25: =+'SEMANA DEL 2 AL 7-3-26'!A25 -> MAYERLIN BOLIVAR
A26: =+A25+1 -> 23 | B26: =+'SEMANA DEL 2 AL 7-3-26'!A26 -> MARTHA SILVA
A27: =+A26+1 -> 24 | B27: =+'SEMANA DEL 2 AL 7-3-26'!#REF! -> #REF!
A28: =+A27+1 -> 25 | B28: =+'SEMANA DEL 2 AL 7-3-26'!#REF! -> #REF!
A29: =+A28+1 -> 26 | B29: =+'SEMANA DEL 2 AL 7-3-26'!A29 -> MARIA MEDINA
A30: =+A29+1 -> 27 | B30: =+'SEMANA DEL 2 AL 7-3-26'!#REF! -> #REF!
A31: =+A30+1 -> 28 | B31: =+'SEMANA DEL 2 AL 7-3-26'!A31 -> RAMON PARRA
A32: =+A31+1 -> 29 | B32: =+'SEMANA DEL 2 AL 7-3-26'!A32 -> SULAY ALMEIDA
A33: =+A32+1 -> 30 | B33: =+'SEMANA DEL 2 AL 7-3-26'!A33 -> RENE ALMEIDA
A34: =+A33+1 -> 31 | B34: =+'SEMANA DEL 2 AL 7-3-26'!A34 -> RUBIELA MARTINEZ
A35: =+A34+1 -> 32 | B35: =+'SEMANA DEL 2 AL 7-3-26'!A35 -> ROSMIRA DURAN
A36: =+A35+1 -> 33 | B36: =+'SEMANA DEL 2 AL 7-3-26'!#REF! -> #REF!
A37: =+A36+1 -> 34 | B37: =+'SEMANA DEL 2 AL 7-3-26'!A36 -> ROSALBA MATAGIRA
A38: =+A37+1 -> 35 | B38: =+'SEMANA DEL 2 AL 7-3-26'!#REF! -> #REF!
A39: =+A38+1 -> 36 | B39: =+'SEMANA DEL 2 AL 7-3-26'!A37 -> STELLA SILVA
A40: =+A39+1 -> 37 | B40: =+'SEMANA DEL 2 AL 7-3-26'!#REF! -> #REF!
...

Sheet ACUM-RES
C1: MES ENERO 2025
D2: =+'ACUM-DET'!BN30 -> #REF!
B4: MATERIALES | C4: SALDO INI | D4: LLEVAN | E4: TOTAL | F4: PAGA | G4: SALDO
B5: CAPA | C5: =+'ACUM-DET'!B39 -> 0 | D5: =+'ACUM-DET'!R39 -> #REF! | E5: =+C5+D5 -> #REF! | F5: =+'ACUM-DET'!AH30 -> #REF! | G5: =E5-F5 -> #REF!
B6: CAPOTE | C6: =+'ACUM-DET'!C39 -> 0 | D6: =+'ACUM-DET'!S39 -> #REF! | E6: =+C6+D6 -> #REF! | F6: =+'ACUM-DET'!AI30 -> #REF! | G6: =E6-F6 -> #REF!
B8: PICADURA FC | C8: =+'ACUM-DET'!D39 -> 0 | D8: =+'ACUM-DET'!T39 -> #REF! | E8: =+C8+D8 -> #REF! | F8: =+'ACUM-DET'!AJ30 -> #REF! | G8: =E8-F8 -> #REF!
E9: =+C9+D9 -> 0 | G9: =E9-F9 -> 0
E10: =+C10+D10 -> 0 | G10: =E10-F10 -> 0
B11: CESTAS | C11: =+'ACUM-DET'!E39 -> 0 | D11: =+'ACUM-DET'!U39 -> #REF! | E11: =+C11+D11 -> #REF! | F11: =+'ACUM-DET'!AK30 -> #REF! | G11: =E11-F11 -> #REF!
B12: SUMINISTROS | E12: =+C12+D12 -> 0 | G12: =E12-F12 -> 0
B13: SACAS | C13: =+'ACUM-DET'!F39 -> 0 | D13: =+'ACUM-DET'!V39 -> #REF! | E13: =+C13+D13 -> #REF! | F13: =+'ACUM-DET'!AL30 -> #REF! | G13: =E13-F13 -> #REF!
B14: GOMA | C14: =+'ACUM-DET'!G39 -> 0 | D14: =+'ACUM-DET'!W39 -> #REF! | E14: =+C14+D14 -> #REF! | F14: =+'ACUM-DET'!AN30 -> #REF! | G14: =E14-F14 -> #REF!
B15: MARCADOR | C15: =+'ACUM-DET'!H39 -> 0 | D15: =+'ACUM-DET'!X30 -> #REF! | E15: =+C15+D15 -> #REF! | F15: =+'ACUM-DET'!AN30 -> #REF! | G15: =E15-F15 -> #REF!
B16: PAPEL | C16: =+'ACUM-DET'!I39 -> 0 | D16: =+'ACUM-DET'!Y30 -> #REF! | E16: =+C16+D16 -> #REF! | F16: =+'ACUM-DET'!AO30 -> #REF! | G16: =E16-F16 -> #REF!
B17: RESORTES | C17: =+'ACUM-DET'!J39 -> 0 | D17: =+'ACUM-DET'!Z30 -> #REF! | E17: =+C17+D17 -> #REF! | F17: =+'ACUM-DET'!AP30 -> #REF! | G17: =E17-F17 -> #REF!
B18: PACORAS | C18: =+'ACUM-DET'!K39 -> 0 | D18: =+'ACUM-DET'!AA30 -> #REF! | E18: =+C18+D18 -> #REF! | F18: =+'ACUM-DET'!AQ30 -> #REF! | G18: =E18-F18 -> #REF!
B19: MAQUINAS | C19: =+'ACUM-DET'!L39 -> 0 | D19: =+'ACUM-DET'!AB30 -> #REF! | E19: =+C19+D19 -> #REF! | F19: =+'ACUM-DET'!AR30 -> #REF! | G19: =E19-F19 -> #REF!
B20: TRAPOS | C20: =+'ACUM-DET'!M39 -> 0 | D20: =+'ACUM-DET'!AC30 -> #REF! | E20: =+C20+D20 -> #REF! | F20: =+'ACUM-DET'!AS30 -> #REF! | G20: =E20-F20 -> #REF!
B21: SILLAS | C21: =+'ACUM-DET'!N39 -> 0 | D21: =+'ACUM-DET'!AD30 -> #REF! | E21: =+C21+D21 -> #REF! | F21: =+'ACUM-DET'!AT30 -> #REF! | G21: =E21-F21 -> #REF!
B22: PRENSA | C22: =+'ACUM-DET'!O39 -> 0 | D22: =+'ACUM-DET'!AE30 -> #REF! | E22: =+C22+D22 -> #REF! | F22: =+'ACUM-DET'!AU30 -> #REF! | G22: =E22-F22 -> #REF!
B23: CORTADORES | C23: =+'ACUM-DET'!P39 -> 0 | D23: =+'ACUM-DET'!AG30 -> #REF! | E23: =+C23+D23 -> #REF! | F23: =+'ACUM-DET'!AW30 -> #REF! | G23: =E23-F23 -> #REF!
C24: =+'ACUM-DET'!Q31 -> 0 | D24: =+'ACUM-DET'!AG31 -> #REF! | E24: =+C24+D24 -> #REF! | F24: =+'ACUM-DET'!AW31 -> #REF! | G24: =E24-F24 -> #REF!
C25: =+'ACUM-DET'!Q32 -> 0 | D25: =+'ACUM-DET'!AG32 -> #REF! | E25: =+C25+D25 -> #REF! | F25: =+'ACUM-DET'!AW32 -> #REF! | G25: =E25-F25 -> #REF!
C26: =+'ACUM-DET'!Q33 -> 0 | D26: =+'ACUM-DET'!AG33 -> #REF! | E26: =+C26+D26 -> #REF! | F26: =+'ACUM-DET'!AW33 -> #REF! | G26: =E26-F26 -> #REF!
C27: =+'ACUM-DET'!Q34 -> 0 | D27: =+'ACUM-DET'!AG34 -> #REF! | E27: =+C27+D27 -> #REF! | F27: =+'ACUM-DET'!AW34 -> #REF! | G27: =E27-F27 -> #REF!
C28: =+'ACUM-DET'!Q35 -> 0 | D28: =+'ACUM-DET'!AG35 -> #REF! | E28: =+C28+D28 -> #REF! | F28: =+'ACUM-DET'!AW35 -> #REF! | G28: =E28-F28 -> #REF!

Sheet ACUM-DET
A1: MES DE ENERO 2025
B2: S A L D O S I N I C I A L E S | R2: L L E V A N | AH2: P A G A N | AX2: SALDOS | BV2: SUMINISTROS | CH2: OTRAS
A3: NOMBRE | B3: CAPA | C3: CAPOTE | D3: PICADURA | E3: CESTA | F3: SACAS | G3: GOMA | H3: MAR | I3: PAPEL | J3: REST | K3: PACORA | L3: MAQ | M3: TRAP | N3: SILLA | O3: PRENS | P3: CORT | Q3: REZAGOS | R3: CAPA | S3: CAPOTE | T3: PICADURA | U3: CESTA | V3: SACAS | W3: GOMA | X3: MAR | Y3: PAPEL | Z3: REST | AA3: PACORA | AB3: MAQ | AC3: TRAP | AD3: SILLA | AE3: PRENS | AF3: CORT | AG3: REZAGOS | AH3: CAPA | AI3: CAPOTE | AJ3: PICADURA | AK3: CESTA | AL3: SACAS | AM3: GOMA | AN3: MAR | AO3: PAPEL | AP3: REST | AQ3: PACORA | AR3: MAQ | AS3: TRAP | AT3: SILLA | AU3: PRENS | AV3: CORT | AW3: REZAGOS | AX3: CAPA | AY3: CAPOTE | AZ3: PICADURA | BA3: CESTA | BB3: SACAS | BC3: GOMA | BD3: MAR | BE3: PAPEL | BF3: REST | BG3: TABL | BH3: MAQ | BI3: TRAP | BJ3: SILLA | BK3: PRENS | BL3: CORT | BM3: REZAGOS | BN3: Tabacos | BO3: SACAS | BP3: GOMA | BQ3: MAR | BR3: PAPEL | BS3: REST | BT3: TABL | BU3: MAQ | BV3: TRAP | BW3: SILLA | BX3: PRENS | BY3: CORT | BZ3: REZAGOS | CA3: PRESTAMO | CB3: AHORROS | CC3: PRECIO CAPA | CD3: PRECIO CAPOTE | CE3: PRECIO PICADURA | CF3: TOTAL MATERIAL | CG3: PRECIO TAB. | CH3: DEDUCCIONES | CI3: TOTAL A PAGAR
A4: =+'SEMANA DEL 2 AL 7-3-26'!A5 -> ALCIDES CORREA | B4: =+'SEMANA DEL 2 AL 7-3-26'!B5 -> 0 | C4: =+'SEMANA DEL 2 AL 7-3-26'!C5 -> 0 | D4: =+'SEMANA DEL 2 AL 7-3-26'!D5 -> 0 | E4: =+'SEMANA DEL 2 AL 7-3-26'!E5 -> 0 | F4: =+'SEMANA DEL 2 AL 7-3-26'!F5 -> 0 | G4: =+'SEMANA DEL 2 AL 7-3-26'!G5 -> 0 | H4: =+'SEMANA DEL 2 AL 7-3-26'!H5 -> 0 | ... Q4: =+'SEMANA DEL 2 AL 7-3-26'!Q5 -> 0 | R4: =+'SEMANA DEL 2 AL 7-3-26'!R5+'SEMANA DEL 7 AL 14'!R5+'SEMANA DEL 14 AL 21 '!R5+'SEMANA DEL 21AL 28-3'!R5+#REF! -> #REF! | S4: =+'SEMANA DEL 2 AL 7-3-26'!S5+'SEMANA DEL 7 AL 14'!S5+'SEMANA DEL 14 AL 21 '!S5+'SEMANA DEL 21AL 28-3'!S5+#REF! -> #REF! | T4: =+'SEMANA DEL 2 AL 7-3-26'!T5+'SEMANA DEL 7 AL 14'!T5+'SEMANA DEL 14 AL 21 '!T5+'SEMANA DEL 21AL 28-3'!T5+#REF! -> #REF! | U4: =+'SEMANA DEL 2 AL 7-3-26'!U5+'SEMANA DEL 7 AL 14'!U5+'SEMANA DEL 14 AL 21 '!U5+'SEMANA DEL 21AL 28-3'!U5+#REF! -> #REF! | V4: =+'SEMANA DEL 2 AL 7-3-26'!V5+'SEMANA DEL 7 AL 14'!V5+'SEMANA DEL 14 AL 21 '!V5+'SEMANA DEL 21AL 28-3'!V5+#REF! -> #REF! | W4: =+'SEMANA DEL 2 AL 7-3-26'!W5+'SEMANA DEL 7 AL 14'!W5+'SEMANA DEL 14 AL 21 '!W5+'SEMANA DEL 21AL 28-3'!W5+#REF! -> #REF! | X4: =+'SEMANA DEL 2 AL 7-3-26'!X5+'SEMANA DEL 7 AL 14'!X5+'SEMANA DEL 14 AL 21 '!X5+'SEMANA DEL 21AL 28-3'!X5+#REF! -> #REF! | Y4: =+'SEMANA DEL 2 AL 7-3-26'!Y5+'SEMANA DEL 7 AL 14'!Y5+'SEMANA DEL 14 AL 21 '!Y5+'SEMANA DEL 21AL 28-3'!Y5+#REF! -> #REF! | ... AW4: =+'SEMANA DEL 2 AL 7-3-26'!AW5+'SEMANA DEL 7 AL 14'!AW5+'SEMANA DEL 14 AL 21 '!AW5+'SEMANA DEL 21AL 28-3'!AW5+#REF! -> #REF! | AX4: =+B4+R4-AH4 -> #REF! | AY4: =+C4+S4-AI4 -> #REF! | AZ4: =+D4+T4-AJ4 -> #REF! | BA4: =+E4+U4-AK4 -> #REF! | BB4: =+F4+V4-AL4 -> #REF! | BC4: =+G4+W4-AM4 -> #REF! | BD4: =+H4+X4-AN4 -> #REF! | BE4: =+I4+Y4-AO4 -> #REF! | ... BM4: =+Q4+AG4-AW4 -> #REF! | BN4: =+'SEMANA DEL 2 AL 7-3-26'!BN5+'SEMANA DEL 7 AL 14'!BN5+'SEMANA DEL 14 AL 21 '!BN5+'SEMANA DEL 21AL 28-3'!BN5+#REF! -> #REF! | BO4: =+'SEMANA DEL 2 AL 7-3-26'!BO5+'SEMANA DEL 7 AL 14'!BO5+'SEMANA DEL 14 AL 21 '!BO5+'SEMANA DEL 21AL 28-3'!BO5+#REF! -> #REF! | BP4: =+'SEMANA DEL 2 AL 7-3-26'!BP5+'SEMANA DEL 7 AL 14'!BP5+'SEMANA DEL 14 AL 21 '!BP5+'SEMANA DEL 21AL 28-3'!BP5+#REF! -> #REF! | BQ4: =+'SEMANA DEL 2 AL 7-3-26'!BQ5+'SEMANA DEL 7 AL 14'!BQ5+'SEMANA DEL 14 AL 21 '!BQ5+'SEMANA DEL 21AL 28-3'!BQ5+#REF! -> #REF! | BR4: =+'SEMANA DEL 2 AL 7-3-26'!BR5+'SEMANA DEL 7 AL 14'!BR5+'SEMANA DEL 14 AL 21 '!BR5+'SEMANA DEL 21AL 28-3'!BR5+#REF! -> #REF! | BS4: =+'SEMANA DEL 2 AL 7-3-26'!BS5+'SEMANA DEL 7 AL 14'!BS5+'SEMANA DEL 14 AL 21 '!BS5+'SEMANA DEL 21AL 28-3'!BS5+#REF! -> #REF! | BT4: =+'SEMANA DEL 2 AL 7-3-26'!BT5+'SEMANA DEL 7 AL 14'!BT5+'SEMANA DEL 14 AL 21 '!BT5+'SEMANA DEL 21AL 28-3'!BT5+#REF! -> #REF! | BU4: =+'SEMANA DEL 2 AL 7-3-26'!BU5+'SEMANA DEL 7 AL 14'!BU5+'SEMANA DEL 14 AL 21 '!BU5+'SEMANA DEL 21AL 28-3'!BU5+#REF! -> #REF! | ... CI4: =+'SEMANA DEL 2 AL 7-3-26'!CI5+'SEMANA DEL 7 AL 14'!CI5+'SEMANA DEL 14 AL 21 '!CI5+'SEMANA DEL 21AL 28-3'!CI5+#REF! -> #REF!
A5: =+'SEMANA DEL 2 AL 7-3-26'!A7 -> BLANCA ALVARADO | B5: =+'SEMANA DEL 2 AL 7-3-26'!B7 -> 0 | C5: =+'SEMANA DEL 2 AL 7-3-26'!C7 -> 0 | D5: =+'SEMANA DEL 2 AL 7-3-26'!D7 -> 0 | E5: =+'SEMANA DEL 2 AL 7-3-26'!E7 -> 0 | F5: =+'SEMANA DEL 2 AL 7-3-26'!F7 -> 0 | G5: =+'SEMANA DEL 2 AL 7-3-26'!G7 -> 0 | H5: =+'SEMANA DEL 2 AL 7-3-26'!H7 -> 0 | ... Q5: =+'SEMANA DEL 2 AL 7-3-26'!Q7 -> 0 | R5: =+'SEMANA DEL 2 AL 7-3-26'!#REF!+'SEMANA DEL 7 AL 14'!R6+'SEMANA DEL 14 AL 21 '!R6+'SEMANA DEL 21AL 28-3'!R7+#REF! -> #REF! | S5: =+'SEMANA DEL 2 AL 7-3-26'!#REF!+'SEMANA DEL 7 AL 14'!S6+'SEMANA DEL 14 AL 21 '!S6+'SEMANA DEL 21AL 28-3'!S7+#REF! -> #REF! | T5: =+'SEMANA DEL 2 AL 7-3-26'!#REF!+'SEMANA DEL 7 AL 14'!T6+'SEMANA DEL 14 AL 21 '!T6+'SEMANA DEL 21AL 28-3'!T7+#REF! -> #REF! | U5: =+'SEMANA DEL 2 AL 7-3-26'!#REF!+'SEMANA DEL 7 AL 14'!U6+'SEMANA DEL 14 AL 21 '!U6+'SEMANA DEL 21AL 28-3'!U7+#REF! -> #REF! | V5: =+'SEMANA DEL 2 AL 7-3-26'!#REF!+'SEMANA DEL 7 AL 14'!V6+'SEMANA DEL 14 AL 21 '!V6+'SEMANA DEL 21AL 28-3'!V7+#REF! -> #REF! | W5: =+'SEMANA DEL 2 AL 7-3-26'!#REF!+'SEMANA DEL 7 AL 14'!W6+'SEMANA DEL 14 AL 21 '!W6+'SEMANA DEL 21AL 28-3'!W7+#REF! -> #REF! | X5: =+'SEMANA DEL 2 AL 7-3-26'!#REF!+'SEMANA DEL 7 AL 14'!X6+'SEMANA DEL 14 AL 21 '!X6+'SEMANA DEL 21AL 28-3'!X7+#REF! -> #REF! | Y5: =+'SEMANA DEL 2 AL 7-3-26'!#REF!+'SEMANA DEL 7 AL 14'!Y6+'SEMANA DEL 14 AL 21 '!Y6+'SEMANA DEL 21AL 28-3'!Y7+#REF! -> #REF! | ... AW5: =+'SEMANA DEL 2 AL 7-3-26'!#REF!+'SEMANA DEL 7 AL 14'!AW6+'SEMANA DEL 14 AL 21 '!AW6+'SEMANA DEL 21AL 28-3'!AW7+#REF! -> #REF! | AX5: =+B5+R5-AH5 -> #REF! | AY5: =+C5+S5-AI5 -> #REF! | AZ5: =+D5+T5-AJ5 -> #REF! | BA5: =+E5+U5-AK5 -> #REF! | BB5: =+F5+V5-AL5 -> #REF! | BC5: =+G5+W5-AM5 -> #REF! | BD5: =+H5+X5-AN5 -> #REF! | BE5: =+I5+Y5-AO5 -> #REF! | ... BM5: =+Q5+AG5-AW5 -> #REF! | BN5: =+'SEMANA DEL 2 AL 7-3-26'!#REF!+'SEMANA DEL 7 AL 14'!BN6+'SEMANA DEL 14 AL 21 '!BN6+'SEMANA DEL 21AL 28-3'!BN7+#REF! -> #REF! | BO5: =+'SEMANA DEL 2 AL 7-3-26'!#REF!+'SEMANA DEL 7 AL 14'!BO6+'SEMANA DEL 14 AL 21 '!BO6+'SEMANA DEL 21AL 28-3'!BO7+#REF! -> #REF! | BP5: =+'SEMANA DEL 2 AL 7-3-26'!#REF!+'SEMANA DEL 7 AL 14'!BP6+'SEMANA DEL 14 AL 21 '!BP6+'SEMANA DEL 21AL 28-3'!BP7+#REF! -> #REF! | BQ5: =+'SEMANA DEL 2 AL 7-3-26'!#REF!+'SEMANA DEL 7 AL 14'!BQ6+'SEMANA DEL 14 AL 21 '!BQ6+'SEMANA DEL 21AL 28-3'!BQ7+#REF! -> #REF! | BR5: =+'SEMANA DEL 2 AL 7-3-26'!#REF!+'SEMANA DEL 7 AL 14'!BR6+'SEMANA DEL 14 AL 21 '!BR6+'SEMANA DEL 21AL 28-3'!BR7+#REF! -> #REF! | BS5: =+'SEMANA DEL 2 AL 7-3-26'!#REF!+'SEMANA DEL 7 AL 14'!BS6+'SEMANA DEL 14 AL 21 '!BS6+'SEMANA DEL 21AL 28-3'!BS7+#REF! -> #REF! | BT5: =+'SEMANA DEL 2 AL 7-3-26'!#REF!+'SEMANA DEL 7 AL 14'!BT6+'SEMANA DEL 14 AL 21 '!BT6+'SEMANA DEL 21AL 28-3'!BT7+#REF! -> #REF! | BU5: =+'SEMANA DEL 2 AL 7-3-26'!#REF!+'SEMANA DEL 7 AL 14'!BU6+'SEMANA DEL 14 AL 21 '!BU6+'SEMANA DEL 21AL 28-3'!BU7+#REF! -> #REF! | ... CI5: =+'SEMANA DEL 2 AL 7-3-26'!#REF!+'SEMANA DEL 7 AL 14'!CI6+'SEMANA DEL 14 AL 21 '!CI6+'SEMANA DEL 21AL 28-3'!CI7+#REF! -> #REF!
A6: =+'SEMANA DEL 2 AL 7-3-26'!#REF! -> #REF! | B6: =+'SEMANA DEL 2 AL 7-3-26'!#REF! -> #REF! | C6: =+'SEMANA DEL 2 AL 7-3-26'!#REF! -> #REF! | D6: =+'SEMANA DEL 2 AL 7-3-26'!#REF! -> #REF! | E6: =+'SEMANA DEL 2 AL 7-3-26'!#REF! -> #REF! | F6: =+'SEMANA DEL 2 AL 7-3-26'!#REF! -> #REF! | G6: =+'SEMANA DEL 2 AL 7-3-26'!#REF! -> #REF! | H6: =+'SEMANA DEL 2 AL 7-3-26'!#REF! -> #REF! | ... Q6: =+'SEMANA DEL 2 AL 7-3-26'!#REF! -> #REF! | R6: =+'SEMANA DEL 2 AL 7-3-26'!R7+'SEMANA DEL 7 AL 14'!#REF!+'SEMANA DEL 14 AL 21 '!#REF!+'SEMANA DEL 21AL 28-3'!#REF!+#REF! -> #REF! | S6: =+'SEMANA DEL 2 AL 7-3-26'!S7+'SEMANA DEL 7 AL 14'!#REF!+'SEMANA DEL 14 AL 21 '!#REF!+'SEMANA DEL 21AL 28-3'!#REF!+#REF! -> #REF! | T6: =+'SEMANA DEL 2 AL 7-3-26'!T7+'SEMANA DEL 7 AL 14'!#REF!+'SEMANA DEL 14 AL 21 '!#REF!+'SEMANA DEL 21AL 28-3'!#REF!+#REF! -> #REF! | U6: =+'SEMANA DEL 2 AL 7-3-26'!U7+'SEMANA DEL 7 AL 14'!#REF!+'SEMANA DEL 14 AL 21 '!#REF!+'SEMANA DEL 21AL 28-3'!#REF!+#REF! -> #REF! | V6: =+'SEMANA DEL 2 AL 7-3-26'!V7+'SEMANA DEL 7 AL 14'!#REF!+'SEMANA DEL 14 AL 21 '!#REF!+'SEMANA DEL 21AL 28-3'!#REF!+#REF! -> #REF! | W6: =+'SEMANA DEL 2 AL 7-3-26'!W7+'SEMANA DEL 7 AL 14'!#REF!+'SEMANA DEL 14 AL 21 '!#REF!+'SEMANA DEL 21AL 28-3'!#REF!+#REF! -> #REF! | X6: =+'SEMANA DEL 2 AL 7-3-26'!X7+'SEMANA DEL 7 AL 14'!#REF!+'SEMANA DEL 14 AL 21 '!#REF!+'SEMANA DEL 21AL 28-3'!#REF!+#REF! -> #REF! | Y6: =+'SEMANA DEL 2 AL 7-3-26'!Y7+'SEMANA DEL 7 AL 14'!#REF!+'SEMANA DEL 14 AL 21 '!#REF!+'SEMANA DEL 21AL 28-3'!#REF!+#REF! -> #REF! | ... AW6: =+'SEMANA DEL 2 AL 7-3-26'!AW7+'SEMANA DEL 7 AL 14'!#REF!+'SEMANA DEL 14 AL 21 '!#REF!+'SEMANA DEL 21AL 28-3'!#REF!+#REF! -> #REF! | AX6: =+B6+R6-AH6 -> #REF! | AY6: =+C6+S6-AI6 -> #REF! | AZ6: =+D6+T6-AJ6 -> #REF! | BA6: =+E6+U6-AK6 -> #REF! | BB6: =+F6+V6-AL6 -> #REF! | BC6: =+G6+W6-AM6 -> #REF! | BD6: =+H6+X6-AN6 -> #REF! | BE6: =+I6+Y6-AO6 -> #REF! | ... BM6: =+Q6+AG6-AW6 -> #REF! | BN6: =+'SEMANA DEL 2 AL 7-3-26'!BN7+'SEMANA DEL 7 AL 14'!#REF!+'SEMANA DEL 14 AL 21 '!#REF!+'SEMANA DEL 21AL 28-3'!#REF!+#REF! -> #REF! | BO6: =+'SEMANA DEL 2 AL 7-3-26'!BO7+'SEMANA DEL 7 AL 14'!#REF!+'SEMANA DEL 14 AL 21 '!#REF!+'SEMANA DEL 21AL 28-3'!#REF!+#REF! -> #REF! | BP6: =+'SEMANA DEL 2 AL 7-3-26'!BP7+'SEMANA DEL 7 AL 14'!#REF!+'SEMANA DEL 14 AL 21 '!#REF!+'SEMANA DEL 21AL 28-3'!#REF!+#REF! -> #REF! | BQ6: =+'SEMANA DEL 2 AL 7-3-26'!BQ7+'SEMANA DEL 7 AL 14'!#REF!+'SEMANA DEL 14 AL 21 '!#REF!+'SEMANA DEL 21AL 28-3'!#REF!+#REF! -> #REF! | BR6: =+'SEMANA DEL 2 AL 7-3-26'!BR7+'SEMANA DEL 7 AL 14'!#REF!+'SEMANA DEL 14 AL 21 '!#REF!+'SEMANA DEL 21AL 28-3'!#REF!+#REF! -> #REF! | BS6: =+'SEMANA DEL 2 AL 7-3-26'!BS7+'SEMANA DEL 7 AL 14'!#REF!+'SEMANA DEL 14 AL 21 '!#REF!+'SEMANA DEL 21AL 28-3'!#REF!+#REF! -> #REF! | BT6: =+'SEMANA DEL 2 AL 7-3-26'!BT7+'SEMANA DEL 7 AL 14'!#REF!+'SEMANA DEL 14 AL 21 '!#REF!+'SEMANA DEL 21AL 28-3'!#REF!+#REF! -> #REF! | BU6: =+'SEMANA DEL 2 AL 7-3-26'!BU7+'SEMANA DEL 7 AL 14'!#REF!+'SEMANA DEL 14 AL 21 '!#REF!+'SEMANA DEL 21AL 28-3'!#REF!+#REF! -> #REF! | ... CI6: =+'SEMANA DEL 2 AL 7-3-26'!CI7+'SEMANA DEL 7 AL 14'!#REF!+'SEMANA DEL 14 AL 21 '!#REF!+'SEMANA DEL 21AL 28-3'!#REF!+#REF! -> #REF!
A7: =+'SEMANA DEL 2 AL 7-3-26'!#REF! -> #REF! | B7: =+'SEMANA DEL 2 AL 7-3-26'!#REF! -> #REF! | C7: =+'SEMANA DEL 2 AL 7-3-26'!#REF! -> #REF! | D7: =+'SEMANA DEL 2 AL 7-3-26'!#REF! -> #REF! | E7: =+'SEMANA DEL 2 AL 7-3-26'!#REF! -> #REF! | F7: =+'SEMANA DEL 2 AL 7-3-26'!#REF! -> #REF! | G7: =+'SEMANA DEL 2 AL 7-3-26'!#REF! -> #REF! | H7: =+'SEMANA DEL 2 AL 7-3-26'!#REF! -> #REF! | ... Q7: =+'SEMANA DEL 2 AL 7-3-26'!#REF! -> #REF! | R7: =+'SEMANA DEL 2 AL 7-3-26'!#REF!+'SEMANA DEL 7 AL 14'!R9+'SEMANA DEL 14 AL 21 '!R9+'SEMANA DEL 21AL 28-3'!R11+#REF! -> #REF! | S7: =+'SEMANA DEL 2 AL 7-3-26'!#REF!+'SEMANA DEL 7 AL 14'!S9+'SEMANA DEL 14 AL 21 '!S9+'SEMANA DEL 21AL 28-3'!S11+#REF! -> #REF! | T7: =+'SEMANA DEL 2 AL 7-3-26'!#REF!+'SEMANA DEL 7 AL 14'!T9+'SEMANA DEL 14 AL 21 '!T9+'SEMANA DEL 21AL 28-3'!T11+#REF! -> #REF! | U7: =+'SEMANA DEL 2 AL 7-3-26'!#REF!+'SEMANA DEL 7 AL 14'!U9+'SEMANA DEL 14 AL 21 '!U9+'SEMANA DEL 21AL 28-3'!U11+#REF! -> #REF! | V7: =+'SEMANA DEL 2 AL 7-3-26'!#REF!+'SEMANA DEL 7 AL 14'!V9+'SEMANA DEL 14 AL 21 '!V9+'SEMANA DEL 21AL 28-3'!V11+#REF! -> #REF! | W7: =+'SEMANA DEL 2 AL 7-3-26'!#REF!+'SEMANA DEL 7 AL 14'!W9+'SEMANA DEL 14 AL 21 '!W9+'SEMANA DEL 21AL 28-3'!W11+#REF! -> #REF! | X7: =+'SEMANA DEL 2 AL 7-3-26'!#REF!+'SEMANA DEL 7 AL 14'!X9+'SEMANA DEL 14 AL 21 '!X9+'SEMANA DEL 21AL 28-3'!X11+#REF! -> #REF! | Y7: =+'SEMANA DEL 2 AL 7-3-26'!#REF!+'SEMANA DEL 7 AL 14'!Y9+'SEMANA DEL 14 AL 21 '!Y9+'SEMANA DEL 21AL 28-3'!Y11+#REF! -> #REF! | ... AW7: =+'SEMANA DEL 2 AL 7-3-26'!#REF!+'SEMANA DEL 7 AL 14'!AW9+'SEMANA DEL 14 AL 21 '!AW9+'SEMANA DEL 21AL 28-3'!AW11+#REF! -> #REF! | AX7: =+B7+R7-AH7 -> #REF! | AY7: =+C7+S7-AI7 -> #REF! | AZ7: =+D7+T7-AJ7 -> #REF! | BA7: =+E7+U7-AK7 -> #REF! | BB7: =+F7+V7-AL7 -> #REF! | BC7: =+G7+W7-AM7 -> #REF! | BD7: =+H7+X7-AN7 -> #REF! | BE7: =+I7+Y7-AO7 -> #REF! | ... BM7: =+Q7+AG7-AW7 -> #REF! | BN7: =+'SEMANA DEL 2 AL 7-3-26'!#REF!+'SEMANA DEL 7 AL 14'!BN9+'SEMANA DEL 14 AL 21 '!BN9+'SEMANA DEL 21AL 28-3'!BN11+#REF! -> #REF! | BO7: =+'SEMANA DEL 2 AL 7-3-26'!#REF!+'SEMANA DEL 7 AL 14'!BO9+'SEMANA DEL 14 AL 21 '!BO9+'SEMANA DEL 21AL 28-3'!BO11+#REF! -> #REF! | BP7: =+'SEMANA DEL 2 AL 7-3-26'!#REF!+'SEMANA DEL 7 AL 14'!BP9+'SEMANA DEL 14 AL 21 '!BP9+'SEMANA DEL 21AL 28-3'!BP11+#REF! -> #REF! | BQ7: =+'SEMANA DEL 2 AL 7-3-26'!#REF!+'SEMANA DEL 7 AL 14'!BQ9+'SEMANA DEL 14 AL 21 '!BQ9+'SEMANA DEL 21AL 28-3'!BQ11+#REF! -> #REF! | BR7: =+'SEMANA DEL 2 AL 7-3-26'!#REF!+'SEMANA DEL 7 AL 14'!BR9+'SEMANA DEL 14 AL 21 '!BR9+'SEMANA DEL 21AL 28-3'!BR11+#REF! -> #REF! | BS7: =+'SEMANA DEL 2 AL 7-3-26'!#REF!+'SEMANA DEL 7 AL 14'!BS9+'SEMANA DEL 14 AL 21 '!BS9+'SEMANA DEL 21AL 28-3'!BS11+#REF! -> #REF! | BT7: =+'SEMANA DEL 2 AL 7-3-26'!#REF!+'SEMANA DEL 7 AL 14'!BT9+'SEMANA DEL 14 AL 21 '!BT9+'SEMANA DEL 21AL 28-3'!BT11+#REF! -> #REF! | BU7: =+'SEMANA DEL 2 AL 7-3-26'!#REF!+'SEMANA DEL 7 AL 14'!BU9+'SEMANA DEL 14 AL 21 '!BU9+'SEMANA DEL 21AL 28-3'!BU11+#REF! -> #REF! | ... CI7: =+'SEMANA DEL 2 AL 7-3-26'!#REF!+'SEMANA DEL 7 AL 14'!CI9+'SEMANA DEL 14 AL 21 '!CI9+'SEMANA DEL 21AL 28-3'!CI11+#REF! -> #REF!
A8: =+'SEMANA DEL 2 AL 7-3-26'!#REF! -> #REF! | B8: =+'SEMANA DEL 2 AL 7-3-26'!#REF! -> #REF! | C8: =+'SEMANA DEL 2 AL 7-3-26'!#REF! -> #REF! | D8: =+'SEMANA DEL 2 AL 7-3-26'!#REF! -> #REF! | E8: =+'SEMANA DEL 2 AL 7-3-26'!#REF! -> #REF! | F8: =+'SEMANA DEL 2 AL 7-3-26'!#REF! -> #REF! | G8: =+'SEMANA DEL 2 AL 7-3-26'!#REF! -> #REF! | H8: =+'SEMANA DEL 2 AL 7-3-26'!#REF! -> #REF! | ... Q8: =+'SEMANA DEL 2 AL 7-3-26'!#REF! -> #REF! | R8: =+'SEMANA DEL 2 AL 7-3-26'!#REF!+'SEMANA DEL 7 AL 14'!R10+'SEMANA DEL 14 AL 21 '!R10+'SEMANA DEL 21AL 28-3'!R12+#REF! -> #REF! | S8: =+'SEMANA DEL 2 AL 7-3-26'!#REF!+'SEMANA DEL 7 AL 14'!S10+'SEMANA DEL 14 AL 21 '!S10+'SEMANA DEL 21AL 28-3'!S12+#REF! -> #REF! | T8: =+'SEMANA DEL 2 AL 7-3-26'!#REF!+'SEMANA DEL 7 AL 14'!T10+'SEMANA DEL 14 AL 21 '!T10+'SEMANA DEL 21AL 28-3'!T12+#REF! -> #REF! | U8: =+'SEMANA DEL 2 AL 7-3-26'!#REF!+'SEMANA DEL 7 AL 14'!U10+'SEMANA DEL 14 AL 21 '!U10+'SEMANA DEL 21AL 28-3'!U12+#REF! -> #REF! | V8: =+'SEMANA DEL 2 AL 7-3-26'!#REF!+'SEMANA DEL 7 AL 14'!V10+'SEMANA DEL 14 AL 21 '!V10+'SEMANA DEL 21AL 28-3'!V12+#REF! -> #REF! | W8: =+'SEMANA DEL 2 AL 7-3-26'!#REF!+'SEMANA DEL 7 AL 14'!W10+'SEMANA DEL 14 AL 21 '!W10+'SEMANA DEL 21AL 28-3'!W12+#REF! -> #REF! | X8: =+'SEMANA DEL 2 AL 7-3-26'!#REF!+'SEMANA DEL 7 AL 14'!X10+'SEMANA DEL 14 AL 21 '!X10+'SEMANA DEL 21AL 28-3'!X12+#REF! -> #REF! | Y8: =+'SEMANA DEL 2 AL 7-3-26'!#REF!+'SEMANA DEL 7 AL 14'!Y10+'SEMANA DEL 14 AL 21 '!Y10+'SEMANA DEL 21AL 28-3'!Y12+#REF! -> #REF! | ... AW8: =+'SEMANA DEL 2 AL 7-3-26'!#REF!+'SEMANA DEL 7 AL 14'!AW10+'SEMANA DEL 14 AL 21 '!AW10+'SEMANA DEL 21AL 28-3'!AW12+#REF! -> #REF! | AX8: =+B8+R8-AH8 -> #REF! | AY8: =+C8+S8-AI8 -> #REF! | AZ8: =+D8+T8-AJ8 -> #REF! | BA8: =+E8+U8-AK8 -> #REF! | BB8: =+F8+V8-AL8 -> #REF! | BC8: =+G8+W8-AM8 -> #REF! | BD8: =+H8+X8-AN8 -> #REF! | BE8: =+I8+Y8-AO8 -> #REF! | ... BM8: =+Q8+AG8-AW8 -> #REF! | BN8: =+'SEMANA DEL 2 AL 7-3-26'!#REF!+'SEMANA DEL 7 AL 14'!BN10+'SEMANA DEL 14 AL 21 '!BN10+'SEMANA DEL 21AL 28-3'!BN12+#REF! -> #REF! | BO8: =+'SEMANA DEL 2 AL 7-3-26'!#REF!+'SEMANA DEL 7 AL 14'!BO10+'SEMANA DEL 14 AL 21 '!BO10+'SEMANA DEL 21AL 28-3'!BO12+#REF! -> #REF! | BP8: =+'SEMANA DEL 2 AL 7-3-26'!#REF!+'SEMANA DEL 7 AL 14'!BP10+'SEMANA DEL 14 AL 21 '!BP10+'SEMANA DEL 21AL 28-3'!BP12+#REF! -> #REF! | BQ8: =+'SEMANA DEL 2 AL 7-3-26'!#REF!+'SEMANA DEL 7 AL 14'!BQ10+'SEMANA DEL 14 AL 21 '!BQ10+'SEMANA DEL 21AL 28-3'!BQ12+#REF! -> #REF! | BR8: =+'SEMANA DEL 2 AL 7-3-26'!#REF!+'SEMANA DEL 7 AL 14'!BR10+'SEMANA DEL 14 AL 21 '!BR10+'SEMANA DEL 21AL 28-3'!BR12+#REF! -> #REF! | BS8: =+'SEMANA DEL 2 AL 7-3-26'!#REF!+'SEMANA DEL 7 AL 14'!BS10+'SEMANA DEL 14 AL 21 '!BS10+'SEMANA DEL 21AL 28-3'!BS12+#REF! -> #REF! | BT8: =+'SEMANA DEL 2 AL 7-3-26'!#REF!+'SEMANA DEL 7 AL 14'!BT10+'SEMANA DEL 14 AL 21 '!BT10+'SEMANA DEL 21AL 28-3'!BT12+#REF! -> #REF! | BU8: =+'SEMANA DEL 2 AL 7-3-26'!#REF!+'SEMANA DEL 7 AL 14'!BU10+'SEMANA DEL 14 AL 21 '!BU10+'SEMANA DEL 21AL 28-3'!BU12+#REF! -> #REF! | ... CI8: =+'SEMANA DEL 2 AL 7-3-26'!#REF!+'SEMANA DEL 7 AL 14'!CI10+'SEMANA DEL 14 AL 21 '!CI10+'SEMANA DEL 21AL 28-3'!CI12+#REF! -> #REF!
A9: =+'SEMANA DEL 2 AL 7-3-26'!A9 -> ELIZABETH REYES SERRANO | B9: =+'SEMANA DEL 2 AL 7-3-26'!B9 -> 0 | C9: =+'SEMANA DEL 2 AL 7-3-26'!C9 -> 0 | D9: =+'SEMANA DEL 2 AL 7-3-26'!D9 -> 0 | E9: =+'SEMANA DEL 2 AL 7-3-26'!E9 -> 0 | F9: =+'SEMANA DEL 2 AL 7-3-26'!F9 -> 0 | G9: =+'SEMANA DEL 2 AL 7-3-26'!G9 -> 0 | H9: =+'SEMANA DEL 2 AL 7-3-26'!H9 -> 0 | ... Q9: =+'SEMANA DEL 2 AL 7-3-26'!Q9 -> 0 | R9: =+'SEMANA DEL 2 AL 7-3-26'!#REF!+'SEMANA DEL 7 AL 14'!R11+'SEMANA DEL 14 AL 21 '!R11+'SEMANA DEL 21AL 28-3'!#REF!+#REF! -> #REF! | S9: =+'SEMANA DEL 2 AL 7-3-26'!#REF!+'SEMANA DEL 7 AL 14'!S11+'SEMANA DEL 14 AL 21 '!S11+'SEMANA DEL 21AL 28-3'!#REF!+#REF! -> #REF! | T9: =+'SEMANA DEL 2 AL 7-3-26'!#REF!+'SEMANA DEL 7 AL 14'!T11+'SEMANA DEL 14 AL 21 '!T11+'SEMANA DEL 21AL 28-3'!#REF!+#REF! -> #REF! | U9: =+'SEMANA DEL 2 AL 7-3-26'!#REF!+'SEMANA DEL 7 AL 14'!U11+'SEMANA DEL 14 AL 21 '!U11+'SEMANA DEL 21AL 28-3'!#REF!+#REF! -> #REF! | V9: =+'SEMANA DEL 2 AL 7-3-26'!#REF!+'SEMANA DEL 7 AL 14'!V11+'SEMANA DEL 14 AL 21 '!V11+'SEMANA DEL 21AL 28-3'!#REF!+#REF! -> #REF! | W9: =+'SEMANA DEL 2 AL 7-3-26'!#REF!+'SEMANA DEL 7 AL 14'!W11+'SEMANA DEL 14 AL 21 '!W11+'SEMANA DEL 21AL 28-3'!#REF!+#REF! -> #REF! | X9: =+'SEMANA DEL 2 AL 7-3-26'!#REF!+'SEMANA DEL 7 AL 14'!X11+'SEMANA DEL 14 AL 21 '!X11+'SEMANA DEL 21AL 28-3'!#REF!+#REF! -> #REF! | Y9: =+'SEMANA DEL 2 AL 7-3-26'!#REF!+'SEMANA DEL 7 AL 14'!Y11+'SEMANA DEL 14 AL 21 '!Y11+'SEMANA DEL 21AL 28-3'!#REF!+#REF! -> #REF! | ... AW9: =+'SEMANA DEL 2 AL 7-3-26'!#REF!+'SEMANA DEL 7 AL 14'!AW11+'SEMANA DEL 14 AL 21 '!AW11+'SEMANA DEL 21AL 28-3'!#REF!+#REF! -> #REF! | AX9: =+B9+R9-AH9 -> #REF! | AY9: =+C9+S9-AI9 -> #REF! | AZ9: =+D9+T9-AJ9 -> #REF! | BA9: =+E9+U9-AK9 -> #REF! | BB9: =+F9+V9-AL9 -> #REF! | BC9: =+G9+W9-AM9 -> #REF! | BD9: =+H9+X9-AN9 -> #REF! | BE9: =+I9+Y9-AO9 -> #REF! | ... BM9: =+Q9+AG9-AW9 -> #REF! | BN9: =+'SEMANA DEL 2 AL 7-3-26'!#REF!+'SEMANA DEL 7 AL 14'!BN11+'SEMANA DEL 14 AL 21 '!BN11+'SEMANA DEL 21AL 28-3'!#REF!+#REF! -> #REF! | BO9: =+'SEMANA DEL 2 AL 7-3-26'!#REF!+'SEMANA DEL 7 AL 14'!BO11+'SEMANA DEL 14 AL 21 '!BO11+'SEMANA DEL 21AL 28-3'!#REF!+#REF! -> #REF! | BP9: =+'SEMANA DEL 2 AL 7-3-26'!#REF!+'SEMANA DEL 7 AL 14'!BP11+'SEMANA DEL 14 AL 21 '!BP11+'SEMANA DEL 21AL 28-3'!#REF!+#REF! -> #REF! | BQ9: =+'SEMANA DEL 2 AL 7-3-26'!#REF!+'SEMANA DEL 7 AL 14'!BQ11+'SEMANA DEL 14 AL 21 '!BQ11+'SEMANA DEL 21AL 28-3'!#REF!+#REF! -> #REF! | BR9: =+'SEMANA DEL 2 AL 7-3-26'!#REF!+'SEMANA DEL 7 AL 14'!BR11+'SEMANA DEL 14 AL 21 '!BR11+'SEMANA DEL 21AL 28-3'!#REF!+#REF! -> #REF! | BS9: =+'SEMANA DEL 2 AL 7-3-26'!#REF!+'SEMANA DEL 7 AL 14'!BS11+'SEMANA DEL 14 AL 21 '!BS11+'SEMANA DEL 21AL 28-3'!#REF!+#REF! -> #REF! | BT9: =+'SEMANA DEL 2 AL 7-3-26'!#REF!+'SEMANA DEL 7 AL 14'!BT11+'SEMANA DEL 14 AL 21 '!BT11+'SEMANA DEL 21AL 28-3'!#REF!+#REF! -> #REF! | BU9: =+'SEMANA DEL 2 AL 7-3-26'!#REF!+'SEMANA DEL 7 AL 14'!BU11+'SEMANA DEL 14 AL 21 '!BU11+'SEMANA DEL 21AL 28-3'!#REF!+#REF! -> #REF! | ... CI9: =+'SEMANA DEL 2 AL 7-3-26'!#REF!+'SEMANA DEL 7 AL 14'!CI11+'SEMANA DEL 14 AL 21 '!CI11+'SEMANA DEL 21AL 28-3'!#REF!+#REF! -> #REF!
A10: =+'SEMANA DEL 2 AL 7-3-26'!A10 -> ELVIRA LOPEZ | B10: =+'SEMANA DEL 2 AL 7-3-26'!B10 -> 0 | C10: =+'SEMANA DEL 2 AL 7-3-26'!C10 -> 0 | D10: =+'SEMANA DEL 2 AL 7-3-26'!D10 -> 0 | E10: =+'SEMANA DEL 2 AL 7-3-26'!E10 -> 0 | F10: =+'SEMANA DEL 2 AL 7-3-26'!F10 -> 0 | G10: =+'SEMANA DEL 2 AL 7-3-26'!G10 -> 0 | H10: =+'SEMANA DEL 2 AL 7-3-26'!H10 -> 0 | ... Q10: =+'SEMANA DEL 2 AL 7-3-26'!Q10 -> 0 | R10: =+'SEMANA DEL 2 AL 7-3-26'!R10+'SEMANA DEL 7 AL 14'!R12+'SEMANA DEL 14 AL 21 '!R12+'SEMANA DEL 21AL 28-3'!R13+#REF! -> #REF! | S10: =+'SEMANA DEL 2 AL 7-3-26'!S10+'SEMANA DEL 7 AL 14'!S12+'SEMANA DEL 14 AL 21 '!S12+'SEMANA DEL 21AL 28-3'!S13+#REF! -> #REF! | T10: =+'SEMANA DEL 2 AL 7-3-26'!T10+'SEMANA DEL 7 AL 14'!T12+'SEMANA DEL 14 AL 21 '!T12+'SEMANA DEL 21AL 28-3'!T13+#REF! -> #REF! | U10: =+'SEMANA DEL 2 AL 7-3-26'!U10+'SEMANA DEL 7 AL 14'!U12+'SEMANA DEL 14 AL 21 '!U12+'SEMANA DEL 21AL 28-3'!U13+#REF! -> #REF! | V10: =+'SEMANA DEL 2 AL 7-3-26'!V10+'SEMANA DEL 7 AL 14'!V12+'SEMANA DEL 14 AL 21 '!V12+'SEMANA DEL 21AL 28-3'!V13+#REF! -> #REF! | W10: =+'SEMANA DEL 2 AL 7-3-26'!W10+'SEMANA DEL 7 AL 14'!W12+'SEMANA DEL 14 AL 21 '!W12+'SEMANA DEL 21AL 28-3'!W13+#REF! -> #REF! | X10: =+'SEMANA DEL 2 AL 7-3-26'!X10+'SEMANA DEL 7 AL 14'!X12+'SEMANA DEL 14 AL 21 '!X12+'SEMANA DEL 21AL 28-3'!X13+#REF! -> #REF! | Y10: =+'SEMANA DEL 2 AL 7-3-26'!Y10+'SEMANA DEL 7 AL 14'!Y12+'SEMANA DEL 14 AL 21 '!Y12+'SEMANA DEL 21AL 28-3'!Y13+#REF! -> #REF! | ... AW10: =+'SEMANA DEL 2 AL 7-3-26'!AW10+'SEMANA DEL 7 AL 14'!AW12+'SEMANA DEL 14 AL 21 '!AW12+'SEMANA DEL 21AL 28-3'!AW13+#REF! -> #REF! | AX10: =+B10+R10-AH10 -> #REF! | AY10: =+C10+S10-AI10 -> #REF! | AZ10: =+D10+T10-AJ10 -> #REF! | BA10: =+E10+U10-AK10 -> #REF! | BB10: =+F10+V10-AL10 -> #REF! | BC10: =+G10+W10-AM10 -> #REF! | BD10: =+H10+X10-AN10 -> #REF! | BE10: =+I10+Y10-AO10 -> #REF! | ... BM10: =+Q10+AG10-AW10 -> #REF! | BN10: =+'SEMANA DEL 2 AL 7-3-26'!BN10+'SEMANA DEL 7 AL 14'!BN12+'SEMANA DEL 14 AL 21 '!BN12+'SEMANA DEL 21AL 28-3'!BN13+#REF! -> #REF! | BO10: =+'SEMANA DEL 2 AL 7-3-26'!BO10+'SEMANA DEL 7 AL 14'!BO12+'SEMANA DEL 14 AL 21 '!BO12+'SEMANA DEL 21AL 28-3'!BO13+#REF! -> #REF! | BP10: =+'SEMANA DEL 2 AL 7-3-26'!BP10+'SEMANA DEL 7 AL 14'!BP12+'SEMANA DEL 14 AL 21 '!BP12+'SEMANA DEL 21AL 28-3'!BP13+#REF! -> #REF! | BQ10: =+'SEMANA DEL 2 AL 7-3-26'!BQ10+'SEMANA DEL 7 AL 14'!BQ12+'SEMANA DEL 14 AL 21 '!BQ12+'SEMANA DEL 21AL 28-3'!BQ13+#REF! -> #REF! | BR10: =+'SEMANA DEL 2 AL 7-3-26'!BR10+'SEMANA DEL 7 AL 14'!BR12+'SEMANA DEL 14 AL 21 '!BR12+'SEMANA DEL 21AL 28-3'!BR13+#REF! -> #REF! | BS10: =+'SEMANA DEL 2 AL 7-3-26'!BS10+'SEMANA DEL 7 AL 14'!BS12+'SEMANA DEL 14 AL 21 '!BS12+'SEMANA DEL 21AL 28-3'!BS13+#REF! -> #REF! | BT10: =+'SEMANA DEL 2 AL 7-3-26'!BT10+'SEMANA DEL 7 AL 14'!BT12+'SEMANA DEL 14 AL 21 '!BT12+'SEMANA DEL 21AL 28-3'!BT13+#REF! -> #REF! | BU10: =+'SEMANA DEL 2 AL 7-3-26'!BU10+'SEMANA DEL 7 AL 14'!BU12+'SEMANA DEL 14 AL 21 '!BU12+'SEMANA DEL 21AL 28-3'!BU13+#REF! -> #REF! | ... CI10: =+'SEMANA DEL 2 AL 7-3-26'!CI10+'SEMANA DEL 7 AL 14'!CI12+'SEMANA DEL 14 AL 21 '!CI12+'SEMANA DEL 21AL 28-3'!CI13+#REF! -> #REF!
A11: =+'SEMANA DEL 2 AL 7-3-26'!A11 -> ERNESTO REYES | B11: =+'SEMANA DEL 2 AL 7-3-26'!B11 -> 0.2 | C11: =+'SEMANA DEL 2 AL 7-3-26'!C11 -> 0.36 | D11: =+'SEMANA DEL 2 AL 7-3-26'!D11 -> 1.4 | E11: =+'SEMANA DEL 2 AL 7-3-26'!E11 -> 0 | F11: =+'SEMANA DEL 2 AL 7-3-26'!F11 -> 0 | G11: =+'SEMANA DEL 2 AL 7-3-26'!G11 -> 0 | H11: =+'SEMANA DEL 2 AL 7-3-26'!H11 -> 0 | ... Q11: =+'SEMANA DEL 2 AL 7-3-26'!Q11 -> 0 | R11: =+'SEMANA DEL 2 AL 7-3-26'!R11+'SEMANA DEL 7 AL 14'!R13+'SEMANA DEL 14 AL 21 '!R13+'SEMANA DEL 21AL 28-3'!R14+#REF! -> #REF! | S11: =+'SEMANA DEL 2 AL 7-3-26'!S11+'SEMANA DEL 7 AL 14'!S13+'SEMANA DEL 14 AL 21 '!S13+'SEMANA DEL 21AL 28-3'!S14+#REF! -> #REF! | T11: =+'SEMANA DEL 2 AL 7-3-26'!T11+'SEMANA DEL 7 AL 14'!T13+'SEMANA DEL 14 AL 21 '!T13+'SEMANA DEL 21AL 28-3'!T14+#REF! -> #REF! | U11: =+'SEMANA DEL 2 AL 7-3-26'!U11+'SEMANA DEL 7 AL 14'!U13+'SEMANA DEL 14 AL 21 '!U13+'SEMANA DEL 21AL 28-3'!U14+#REF! -> #REF! | V11: =+'SEMANA DEL 2 AL 7-3-26'!V11+'SEMANA DEL 7 AL 14'!V13+'SEMANA DEL 14 AL 21 '!V13+'SEMANA DEL 21AL 28-3'!V14+#REF! -> #REF! | W11: =+'SEMANA DEL 2 AL 7-3-26'!W11+'SEMANA DEL 7 AL 14'!W13+'SEMANA DEL 14 AL 21 '!W13+'SEMANA DEL 21AL 28-3'!W14+#REF! -> #REF! | X11: =+'SEMANA DEL 2 AL 7-3-26'!X11+'SEMANA DEL 7 AL 14'!X13+'SEMANA DEL 14 AL 21 '!X13+'SEMANA DEL 21AL 28-3'!X14+#REF! -> #REF! | Y11: =+'SEMANA DEL 2 AL 7-3-26'!Y11+'SEMANA DEL 7 AL 14'!Y13+'SEMANA DEL 14 AL 21 '!Y13+'SEMANA DEL 21AL 28-3'!Y14+#REF! -> #REF! | ... AW11: =+'SEMANA DEL 2 AL 7-3-26'!AW11+'SEMANA DEL 7 AL 14'!AW13+'SEMANA DEL 14 AL 21 '!AW13+'SEMANA DEL 21AL 28-3'!AW14+#REF! -> #REF! | AX11: =+B11+R11-AH11 -> #REF! | AY11: =+C11+S11-AI11 -> #REF! | AZ11: =+D11+T11-AJ11 -> #REF! | BA11: =+E11+U11-AK11 -> #REF! | BB11: =+F11+V11-AL11 -> #REF! | BC11: =+G11+W11-AM11 -> #REF! | BD11: =+H11+X11-AN11 -> #REF! | BE11: =+I11+Y11-AO11 -> #REF! | ... BM11: =+Q11+AG11-AW11 -> #REF! | BN11: =+'SEMANA DEL 2 AL 7-3-26'!BN11+'SEMANA DEL 7 AL 14'!BN13+'SEMANA DEL 14 AL 21 '!BN13+'SEMANA DEL 21AL 28-3'!BN14+#REF! -> #REF! | BO11: =+'SEMANA DEL 2 AL 7-3-26'!BO11+'SEMANA DEL 7 AL 14'!BO13+'SEMANA DEL 14 AL 21 '!BO13+'SEMANA DEL 21AL 28-3'!BO14+#REF! -> #REF! | BP11: =+'SEMANA DEL 2 AL 7-3-26'!BP11+'SEMANA DEL 7 AL 14'!BP13+'SEMANA DEL 14 AL 21 '!BP13+'SEMANA DEL 21AL 28-3'!BP14+#REF! -> #REF! | BQ11: =+'SEMANA DEL 2 AL 7-3-26'!BQ11+'SEMANA DEL 7 AL 14'!BQ13+'SEMANA DEL 14 AL 21 '!BQ13+'SEMANA DEL 21AL 28-3'!BQ14+#REF! -> #REF! | BR11: =+'SEMANA DEL 2 AL 7-3-26'!BR11+'SEMANA DEL 7 AL 14'!BR13+'SEMANA DEL 14 AL 21 '!BR13+'SEMANA DEL 21AL 28-3'!BR14+#REF! -> #REF! | BS11: =+'SEMANA DEL 2 AL 7-3-26'!BS11+'SEMANA DEL 7 AL 14'!BS13+'SEMANA DEL 14 AL 21 '!BS13+'SEMANA DEL 21AL 28-3'!BS14+#REF! -> #REF! | BT11: =+'SEMANA DEL 2 AL 7-3-26'!BT11+'SEMANA DEL 7 AL 14'!BT13+'SEMANA DEL 14 AL 21 '!BT13+'SEMANA DEL 21AL 28-3'!BT14+#REF! -> #REF! | BU11: =+'SEMANA DEL 2 AL 7-3-26'!BU11+'SEMANA DEL 7 AL 14'!BU13+'SEMANA DEL 14 AL 21 '!BU13+'SEMANA DEL 21AL 28-3'!BU14+#REF! -> #REF! | ... CI11: =+'SEMANA DEL 2 AL 7-3-26'!CI11+'SEMANA DEL 7 AL 14'!CI13+'SEMANA DEL 14 AL 21 '!CI13+'SEMANA DEL 21AL 28-3'!CI14+#REF! -> #REF!
A12: =+'SEMANA DEL 2 AL 7-3-26'!A12 -> GUILLERMO ZAMBRANO | B12: =+'SEMANA DEL 2 AL 7-3-26'!B12 -> 0.35 | C12: =+'SEMANA DEL 2 AL 7-3-26'!C12 -> 1.63 | D12: =+'SEMANA DEL 2 AL 7-3-26'!D12 -> 4.45 | E12: =+'SEMANA DEL 2 AL 7-3-26'!E12 -> 0 | F12: =+'SEMANA DEL 2 AL 7-3-26'!F12 -> 0 | G12: =+'SEMANA DEL 2 AL 7-3-26'!G12 -> 0 | H12: =+'SEMANA DEL 2 AL 7-3-26'!H12 -> 0 | ... Q12: =+'SEMANA DEL 2 AL 7-3-26'!Q12 -> 0 | R12: =+'SEMANA DEL 2 AL 7-3-26'!R12+'SEMANA DEL 7 AL 14'!R16+'SEMANA DEL 14 AL 21 '!R16+'SEMANA DEL 21AL 28-3'!R17+#REF! -> #REF! | S12: =+'SEMANA DEL 2 AL 7-3-26'!S12+'SEMANA DEL 7 AL 14'!S16+'SEMANA DEL 14 AL 21 '!S16+'SEMANA DEL 21AL 28-3'!S17+#REF! -> #REF! | T12: =+'SEMANA DEL 2 AL 7-3-26'!T12+'SEMANA DEL 7 AL 14'!T16+'SEMANA DEL 14 AL 21 '!T16+'SEMANA DEL 21AL 28-3'!T17+#REF! -> #REF! | U12: =+'SEMANA DEL 2 AL 7-3-26'!U12+'SEMANA DEL 7 AL 14'!U16+'SEMANA DEL 14 AL 21 '!U16+'SEMANA DEL 21AL 28-3'!U17+#REF! -> #REF! | V12: =+'SEMANA DEL 2 AL 7-3-26'!V12+'SEMANA DEL 7 AL 14'!V16+'SEMANA DEL 14 AL 21 '!V16+'SEMANA DEL 21AL 28-3'!V17+#REF! -> #REF! | W12: =+'SEMANA DEL 2 AL 7-3-26'!W12+'SEMANA DEL 7 AL 14'!W16+'SEMANA DEL 14 AL 21 '!W16+'SEMANA DEL 21AL 28-3'!W17+#REF! -> #REF! | X12: =+'SEMANA DEL 2 AL 7-3-26'!X12+'SEMANA DEL 7 AL 14'!X16+'SEMANA DEL 14 AL 21 '!X16+'SEMANA DEL 21AL 28-3'!X17+#REF! -> #REF! | Y12: =+'SEMANA DEL 2 AL 7-3-26'!Y12+'SEMANA DEL 7 AL 14'!Y16+'SEMANA DEL 14 AL 21 '!Y16+'SEMANA DEL 21AL 28-3'!Y17+#REF! -> #REF! | ... AW12: =+'SEMANA DEL 2 AL 7-3-26'!AW12+'SEMANA DEL 7 AL 14'!AW16+'SEMANA DEL 14 AL 21 '!AW16+'SEMANA DEL 21AL 28-3'!AW17+#REF! -> #REF! | AX12: =+B12+R12-AH12 -> #REF! | AY12: =+C12+S12-AI12 -> #REF! | AZ12: =+D12+T12-AJ12 -> #REF! | BA12: =+E12+U12-AK12 -> #REF! | BB12: =+F12+V12-AL12 -> #REF! | BC12: =+G12+W12-AM12 -> #REF! | BD12: =+H12+X12-AN12 -> #REF! | BE12: =+I12+Y12-AO12 -> #REF! | ... BM12: =+Q12+AG12-AW12 -> #REF! | BN12: =+'SEMANA DEL 2 AL 7-3-26'!BN12+'SEMANA DEL 7 AL 14'!BN16+'SEMANA DEL 14 AL 21 '!BN16+'SEMANA DEL 21AL 28-3'!BN17+#REF! -> #REF! | BO12: =+'SEMANA DEL 2 AL 7-3-26'!BO12+'SEMANA DEL 7 AL 14'!BO16+'SEMANA DEL 14 AL 21 '!BO16+'SEMANA DEL 21AL 28-3'!BO17+#REF! -> #REF! | BP12: =+'SEMANA DEL 2 AL 7-3-26'!BP12+'SEMANA DEL 7 AL 14'!BP16+'SEMANA DEL 14 AL 21 '!BP16+'SEMANA DEL 21AL 28-3'!BP17+#REF! -> #REF! | BQ12: =+'SEMANA DEL 2 AL 7-3-26'!BQ12+'SEMANA DEL 7 AL 14'!BQ16+'SEMANA DEL 14 AL 21 '!BQ16+'SEMANA DEL 21AL 28-3'!BQ17+#REF! -> #REF! | BR12: =+'SEMANA DEL 2 AL 7-3-26'!BR12+'SEMANA DEL 7 AL 14'!BR16+'SEMANA DEL 14 AL 21 '!BR16+'SEMANA DEL 21AL 28-3'!BR17+#REF! -> #REF! | BS12: =+'SEMANA DEL 2 AL 7-3-26'!BS12+'SEMANA DEL 7 AL 14'!BS16+'SEMANA DEL 14 AL 21 '!BS16+'SEMANA DEL 21AL 28-3'!BS17+#REF! -> #REF! | BT12: =+'SEMANA DEL 2 AL 7-3-26'!BT12+'SEMANA DEL 7 AL 14'!BT16+'SEMANA DEL 14 AL 21 '!BT16+'SEMANA DEL 21AL 28-3'!BT17+#REF! -> #REF! | BU12: =+'SEMANA DEL 2 AL 7-3-26'!BU12+'SEMANA DEL 7 AL 14'!BU16+'SEMANA DEL 14 AL 21 '!BU16+'SEMANA DEL 21AL 28-3'!BU17+#REF! -> #REF! | ... CI12: =+'SEMANA DEL 2 AL 7-3-26'!CI12+'SEMANA DEL 7 AL 14'!CI16+'SEMANA DEL 14 AL 21 '!CI16+'SEMANA DEL 21AL 28-3'!CI17+#REF! -> #REF!
A13: =+'SEMANA DEL 2 AL 7-3-26'!#REF! -> #REF! | B13: =+'SEMANA DEL 2 AL 7-3-26'!#REF! -> #REF! | C13: =+'SEMANA DEL 2 AL 7-3-26'!#REF! -> #REF! | D13: =+'SEMANA DEL 2 AL 7-3-26'!#REF! -> #REF! | E13: =+'SEMANA DEL 2 AL 7-3-26'!#REF! -> #REF! | F13: =+'SEMANA DEL 2 AL 7-3-26'!#REF! -> #REF! | G13: =+'SEMANA DEL 2 AL 7-3-26'!#REF! -> #REF! | H13: =+'SEMANA DEL 2 AL 7-3-26'!#REF! -> #REF! | ... Q13: =+'SEMANA DEL 2 AL 7-3-26'!#REF! -> #REF! | R13: =+'SEMANA DEL 2 AL 7-3-26'!R13+'SEMANA DEL 7 AL 14'!R17+'SEMANA DEL 14 AL 21 '!R17+'SEMANA DEL 21AL 28-3'!R18+#REF! -> #REF! | S13: =+'SEMANA DEL 2 AL 7-3-26'!S13+'SEMANA DEL 7 AL 14'!S17+'SEMANA DEL 14 AL 21 '!S17+'SEMANA DEL 21AL 28-3'!S18+#REF! -> #REF! | T13: =+'SEMANA DEL 2 AL 7-3-26'!T13+'SEMANA DEL 7 AL 14'!T17+'SEMANA DEL 14 AL 21 '!T17+'SEMANA DEL 21AL 28-3'!T18+#REF! -> #REF! | U13: =+'SEMANA DEL 2 AL 7-3-26'!U13+'SEMANA DEL 7 AL 14'!U17+'SEMANA DEL 14 AL 21 '!U17+'SEMANA DEL 21AL 28-3'!U18+#REF! -> #REF! | V13: =+'SEMANA DEL 2 AL 7-3-26'!V13+'SEMANA DEL 7 AL 14'!V17+'SEMANA DEL 14 AL 21 '!V17+'SEMANA DEL 21AL 28-3'!V18+#REF! -> #REF! | W13: =+'SEMANA DEL 2 AL 7-3-26'!W13+'SEMANA DEL 7 AL 14'!W17+'SEMANA DEL 14 AL 21 '!W17+'SEMANA DEL 21AL 28-3'!W18+#REF! -> #REF! | X13: =+'SEMANA DEL 2 AL 7-3-26'!X13+'SEMANA DEL 7 AL 14'!X17+'SEMANA DEL 14 AL 21 '!X17+'SEMANA DEL 21AL 28-3'!X18+#REF! -> #REF! | Y13: =+'SEMANA DEL 2 AL 7-3-26'!Y13+'SEMANA DEL 7 AL 14'!Y17+'SEMANA DEL 14 AL 21 '!Y17+'SEMANA DEL 21AL 28-3'!Y18+#REF! -> #REF! | ... AW13: =+'SEMANA DEL 2 AL 7-3-26'!AW13+'SEMANA DEL 7 AL 14'!AW17+'SEMANA DEL 14 AL 21 '!AW17+'SEMANA DEL 21AL 28-3'!AW18+#REF! -> #REF! | AX13: =+B13+R13-AH13 -> #REF! | AY13: =+C13+S13-AI13 -> #REF! | AZ13: =+D13+T13-AJ13 -> #REF! | BA13: =+E13+U13-AK13 -> #REF! | BB13: =+F13+V13-AL13 -> #REF! | BC13: =+G13+W13-AM13 -> #REF! | BD13: =+H13+X13-AN13 -> #REF! | BE13: =+I13+Y13-AO13 -> #REF! | ... BM13: =+Q13+AG13-AW13 -> #REF! | BN13: =+'SEMANA DEL 2 AL 7-3-26'!BN13+'SEMANA DEL 7 AL 14'!BN17+'SEMANA DEL 14 AL 21 '!BN17+'SEMANA DEL 21AL 28-3'!BN18+#REF! -> #REF! | BO13: =+'SEMANA DEL 2 AL 7-3-26'!BO13+'SEMANA DEL 7 AL 14'!BO17+'SEMANA DEL 14 AL 21 '!BO17+'SEMANA DEL 21AL 28-3'!BO18+#REF! -> #REF! | BP13: =+'SEMANA DEL 2 AL 7-3-26'!BP13+'SEMANA DEL 7 AL 14'!BP17+'SEMANA DEL 14 AL 21 '!BP17+'SEMANA DEL 21AL 28-3'!BP18+#REF! -> #REF! | BQ13: =+'SEMANA DEL 2 AL 7-3-26'!BQ13+'SEMANA DEL 7 AL 14'!BQ17+'SEMANA DEL 14 AL 21 '!BQ17+'SEMANA DEL 21AL 28-3'!BQ18+#REF! -> #REF! | BR13: =+'SEMANA DEL 2 AL 7-3-26'!BR13+'SEMANA DEL 7 AL 14'!BR17+'SEMANA DEL 14 AL 21 '!BR17+'SEMANA DEL 21AL 28-3'!BR18+#REF! -> #REF! | BS13: =+'SEMANA DEL 2 AL 7-3-26'!BS13+'SEMANA DEL 7 AL 14'!BS17+'SEMANA DEL 14 AL 21 '!BS17+'SEMANA DEL 21AL 28-3'!BS18+#REF! -> #REF! | BT13: =+'SEMANA DEL 2 AL 7-3-26'!BT13+'SEMANA DEL 7 AL 14'!BT17+'SEMANA DEL 14 AL 21 '!BT17+'SEMANA DEL 21AL 28-3'!BT18+#REF! -> #REF! | BU13: =+'SEMANA DEL 2 AL 7-3-26'!BU13+'SEMANA DEL 7 AL 14'!BU17+'SEMANA DEL 14 AL 21 '!BU17+'SEMANA DEL 21AL 28-3'!BU18+#REF! -> #REF! | ... CI13: =+'SEMANA DEL 2 AL 7-3-26'!CI13+'SEMANA DEL 7 AL 14'!CI17+'SEMANA DEL 14 AL 21 '!CI17+'SEMANA DEL 21AL 28-3'!CI18+#REF! -> #REF!
A14: =+'SEMANA DEL 2 AL 7-3-26'!A13 -> HUGO ALMEIDA | B14: =+'SEMANA DEL 2 AL 7-3-26'!B13 -> 0 | C14: =+'SEMANA DEL 2 AL 7-3-26'!C13 -> 0 | D14: =+'SEMANA DEL 2 AL 7-3-26'!D13 -> 0 | E14: =+'SEMANA DEL 2 AL 7-3-26'!E13 -> 0 | F14: =+'SEMANA DEL 2 AL 7-3-26'!F13 -> 0 | G14: =+'SEMANA DEL 2 AL 7-3-26'!G13 -> 0 | H14: =+'SEMANA DEL 2 AL 7-3-26'!H13 -> 0 | ... Q14: =+'SEMANA DEL 2 AL 7-3-26'!Q13 -> 0 | R14: =+'SEMANA DEL 2 AL 7-3-26'!R14+'SEMANA DEL 7 AL 14'!#REF!+'SEMANA DEL 14 AL 21 '!#REF!+'SEMANA DEL 21AL 28-3'!#REF!+#REF! -> #REF! | S14: =+'SEMANA DEL 2 AL 7-3-26'!S14+'SEMANA DEL 7 AL 14'!#REF!+'SEMANA DEL 14 AL 21 '!#REF!+'SEMANA DEL 21AL 28-3'!#REF!+#REF! -> #REF! | T14: =+'SEMANA DEL 2 AL 7-3-26'!T14+'SEMANA DEL 7 AL 14'!#REF!+'SEMANA DEL 14 AL 21 '!#REF!+'SEMANA DEL 21AL 28-3'!#REF!+#REF! -> #REF! | U14: =+'SEMANA DEL 2 AL 7-3-26'!U14+'SEMANA DEL 7 AL 14'!#REF!+'SEMANA DEL 14 AL 21 '!#REF!+'SEMANA DEL 21AL 28-3'!#REF!+#REF! -> #REF! | V14: =+'SEMANA DEL 2 AL 7-3-26'!V14+'SEMANA DEL 7 AL 14'!#REF!+'SEMANA DEL 14 AL 21 '!#REF!+'SEMANA DEL 21AL 28-3'!#REF!+#REF! -> #REF! | W14: =+'SEMANA DEL 2 AL 7-3-26'!W14+'SEMANA DEL 7 AL 14'!#REF!+'SEMANA DEL 14 AL 21 '!#REF!+'SEMANA DEL 21AL 28-3'!#REF!+#REF! -> #REF! | X14: =+'SEMANA DEL 2 AL 7-3-26'!X14+'SEMANA DEL 7 AL 14'!#REF!+'SEMANA DEL 14 AL 21 '!#REF!+'SEMANA DEL 21AL 28-3'!#REF!+#REF! -> #REF! | Y14: =+'SEMANA DEL 2 AL 7-3-26'!Y14+'SEMANA DEL 7 AL 14'!#REF!+'SEMANA DEL 14 AL 21 '!#REF!+'SEMANA DEL 21AL 28-3'!#REF!+#REF! -> #REF! | ... AW14: =+'SEMANA DEL 2 AL 7-3-26'!AW14+'SEMANA DEL 7 AL 14'!#REF!+'SEMANA DEL 14 AL 21 '!#REF!+'SEMANA DEL 21AL 28-3'!#REF!+#REF! -> #REF! | AX14: =+B14+R14-AH14 -> #REF! | AY14: =+C14+S14-AI14 -> #REF! | AZ14: =+D14+T14-AJ14 -> #REF! | BA14: =+E14+U14-AK14 -> #REF! | BB14: =+F14+V14-AL14 -> #REF! | BC14: =+G14+W14-AM14 -> #REF! | BD14: =+H14+X14-AN14 -> #REF! | BE14: =+I14+Y14-AO14 -> #REF! | ... BM14: =+Q14+AG14-AW14 -> #REF! | BN14: =+'SEMANA DEL 2 AL 7-3-26'!BN14+'SEMANA DEL 7 AL 14'!#REF!+'SEMANA DEL 14 AL 21 '!#REF!+'SEMANA DEL 21AL 28-3'!#REF!+#REF! -> #REF! | BO14: =+'SEMANA DEL 2 AL 7-3-26'!BO14+'SEMANA DEL 7 AL 14'!#REF!+'SEMANA DEL 14 AL 21 '!#REF!+'SEMANA DEL 21AL 28-3'!#REF!+#REF! -> #REF! | BP14: =+'SEMANA DEL 2 AL 7-3-26'!BP14+'SEMANA DEL 7 AL 14'!#REF!+'SEMANA DEL 14 AL 21 '!#REF!+'SEMANA DEL 21AL 28-3'!#REF!+#REF! -> #REF! | BQ14: =+'SEMANA DEL 2 AL 7-3-26'!BQ14+'SEMANA DEL 7 AL 14'!#REF!+'SEMANA DEL 14 AL 21 '!#REF!+'SEMANA DEL 21AL 28-3'!#REF!+#REF! -> #REF! | BR14: =+'SEMANA DEL 2 AL 7-3-26'!BR14+'SEMANA DEL 7 AL 14'!#REF!+'SEMANA DEL 14 AL 21 '!#REF!+'SEMANA DEL 21AL 28-3'!#REF!+#REF! -> #REF! | BS14: =+'SEMANA DEL 2 AL 7-3-26'!BS14+'SEMANA DEL 7 AL 14'!#REF!+'SEMANA DEL 14 AL 21 '!#REF!+'SEMANA DEL 21AL 28-3'!#REF!+#REF! -> #REF! | BT14: =+'SEMANA DEL 2 AL 7-3-26'!BT14+'SEMANA DEL 7 AL 14'!#REF!+'SEMANA DEL 14 AL 21 '!#REF!+'SEMANA DEL 21AL 28-3'!#REF!+#REF! -> #REF! | BU14: =+'SEMANA DEL 2 AL 7-3-26'!BU14+'SEMANA DEL 7 AL 14'!#REF!+'SEMANA DEL 14 AL 21 '!#REF!+'SEMANA DEL 21AL 28-3'!#REF!+#REF! -> #REF! | ... CI14: =+'SEMANA DEL 2 AL 7-3-26'!CI14+'SEMANA DEL 7 AL 14'!#REF!+'SEMANA DEL 14 AL 21 '!#REF!+'SEMANA DEL 21AL 28-3'!#REF!+#REF! -> #REF!
A15: =+'SEMANA DEL 2 AL 7-3-26'!A14 -> HILDA SERRANO | B15: =+'SEMANA DEL 2 AL 7-3-26'!B14 -> 1 | C15: =+'SEMANA DEL 2 AL 7-3-26'!C14 -> 1.8 | D15: =+'SEMANA DEL 2 AL 7-3-26'!D14 -> 7 | E15: =+'SEMANA DEL 2 AL 7-3-26'!E14 -> 0 | F15: =+'SEMANA DEL 2 AL 7-3-26'!F14 -> 0 | G15: =+'SEMANA DEL 2 AL 7-3-26'!G14 -> 0 | H15: =+'SEMANA DEL 2 AL 7-3-26'!H14 -> 0 | ... Q15: =+'SEMANA DEL 2 AL 7-3-26'!Q14 -> 0 | R15: =+'SEMANA DEL 2 AL 7-3-26'!R16+'SEMANA DEL 7 AL 14'!R20+'SEMANA DEL 14 AL 21 '!R20+'SEMANA DEL 21AL 28-3'!R21+#REF! -> #REF! | S15: =+'SEMANA DEL 2 AL 7-3-26'!S16+'SEMANA DEL 7 AL 14'!S20+'SEMANA DEL 14 AL 21 '!S20+'SEMANA DEL 21AL 28-3'!S21+#REF! -> #REF! | T15: =+'SEMANA DEL 2 AL 7-3-26'!T16+'SEMANA DEL 7 AL 14'!T20+'SEMANA DEL 14 AL 21 '!T20+'SEMANA DEL 21AL 28-3'!T21+#REF! -> #REF! | U15: =+'SEMANA DEL 2 AL 7-3-26'!U16+'SEMANA DEL 7 AL 14'!U20+'SEMANA DEL 14 AL 21 '!U20+'SEMANA DEL 21AL 28-3'!U21+#REF! -> #REF! | V15: =+'SEMANA DEL 2 AL 7-3-26'!V16+'SEMANA DEL 7 AL 14'!V20+'SEMANA DEL 14 AL 21 '!V20+'SEMANA DEL 21AL 28-3'!V21+#REF! -> #REF! | W15: =+'SEMANA DEL 2 AL 7-3-26'!W16+'SEMANA DEL 7 AL 14'!W20+'SEMANA DEL 14 AL 21 '!W20+'SEMANA DEL 21AL 28-3'!W21+#REF! -> #REF! | X15: =+'SEMANA DEL 2 AL 7-3-26'!X16+'SEMANA DEL 7 AL 14'!X20+'SEMANA DEL 14 AL 21 '!X20+'SEMANA DEL 21AL 28-3'!X21+#REF! -> #REF! | Y15: =+'SEMANA DEL 2 AL 7-3-26'!Y16+'SEMANA DEL 7 AL 14'!Y20+'SEMANA DEL 14 AL 21 '!Y20+'SEMANA DEL 21AL 28-3'!Y21+#REF! -> #REF! | ... AW15: =+'SEMANA DEL 2 AL 7-3-26'!AW16+'SEMANA DEL 7 AL 14'!AW20+'SEMANA DEL 14 AL 21 '!AW20+'SEMANA DEL 21AL 28-3'!AW21+#REF! -> #REF! | AX15: =+B15+R15-AH15 -> #REF! | AY15: =+C15+S15-AI15 -> #REF! | AZ15: =+D15+T15-AJ15 -> #REF! | BA15: =+E15+U15-AK15 -> #REF! | BB15: =+F15+V15-AL15 -> #REF! | BC15: =+G15+W15-AM15 -> #REF! | BD15: =+H15+X15-AN15 -> #REF! | BE15: =+I15+Y15-AO15 -> #REF! | ... BM15: =+Q15+AG15-AW15 -> #REF! | BN15: =+'SEMANA DEL 2 AL 7-3-26'!BN16+'SEMANA DEL 7 AL 14'!BN20+'SEMANA DEL 14 AL 21 '!BN20+'SEMANA DEL 21AL 28-3'!BN21+#REF! -> #REF! | BO15: =+'SEMANA DEL 2 AL 7-3-26'!BO16+'SEMANA DEL 7 AL 14'!BO20+'SEMANA DEL 14 AL 21 '!BO20+'SEMANA DEL 21AL 28-3'!BO21+#REF! -> #REF! | BP15: =+'SEMANA DEL 2 AL 7-3-26'!BP16+'SEMANA DEL 7 AL 14'!BP20+'SEMANA DEL 14 AL 21 '!BP20+'SEMANA DEL 21AL 28-3'!BP21+#REF! -> #REF! | BQ15: =+'SEMANA DEL 2 AL 7-3-26'!BQ16+'SEMANA DEL 7 AL 14'!BQ20+'SEMANA DEL 14 AL 21 '!BQ20+'SEMANA DEL 21AL 28-3'!BQ21+#REF! -> #REF! | BR15: =+'SEMANA DEL 2 AL 7-3-26'!BR16+'SEMANA DEL 7 AL 14'!BR20+'SEMANA DEL 14 AL 21 '!BR20+'SEMANA DEL 21AL 28-3'!BR21+#REF! -> #REF! | BS15: =+'SEMANA DEL 2 AL 7-3-26'!BS16+'SEMANA DEL 7 AL 14'!BS20+'SEMANA DEL 14 AL 21 '!BS20+'SEMANA DEL 21AL 28-3'!BS21+#REF! -> #REF! | BT15: =+'SEMANA DEL 2 AL 7-3-26'!BT16+'SEMANA DEL 7 AL 14'!BT20+'SEMANA DEL 14 AL 21 '!BT20+'SEMANA DEL 21AL 28-3'!BT21+#REF! -> #REF! | BU15: =+'SEMANA DEL 2 AL 7-3-26'!BU16+'SEMANA DEL 7 AL 14'!BU20+'SEMANA DEL 14 AL 21 '!BU20+'SEMANA DEL 21AL 28-3'!BU21+#REF! -> #REF! | ... CI15: =+'SEMANA DEL 2 AL 7-3-26'!CI16+'SEMANA DEL 7 AL 14'!CI20+'SEMANA DEL 14 AL 21 '!CI20+'SEMANA DEL 21AL 28-3'!CI21+#REF! -> #REF!
A16: =+'SEMANA DEL 2 AL 7-3-26'!A16 -> JOSE EBLAN GIRON | B16: =+'SEMANA DEL 2 AL 7-3-26'!B16 -> 0.2 | C16: =+'SEMANA DEL 2 AL 7-3-26'!C16 -> 0.36 | D16: =+'SEMANA DEL 2 AL 7-3-26'!D16 -> 1.4 | E16: =+'SEMANA DEL 2 AL 7-3-26'!E16 -> 1 | F16: =+'SEMANA DEL 2 AL 7-3-26'!F16 -> 0 | G16: =+'SEMANA DEL 2 AL 7-3-26'!G16 -> 0 | H16: =+'SEMANA DEL 2 AL 7-3-26'!H16 -> 0 | ... Q16: =+'SEMANA DEL 2 AL 7-3-26'!Q16 -> 0 | R16: =+'SEMANA DEL 2 AL 7-3-26'!R17+'SEMANA DEL 7 AL 14'!R23+'SEMANA DEL 14 AL 21 '!R21+'SEMANA DEL 21AL 28-3'!R22+#REF! -> #REF! | S16: =+'SEMANA DEL 2 AL 7-3-26'!S17+'SEMANA DEL 7 AL 14'!S23+'SEMANA DEL 14 AL 21 '!S21+'SEMANA DEL 21AL 28-3'!S22+#REF! -> #REF! | T16: =+'SEMANA DEL 2 AL 7-3-26'!T17+'SEMANA DEL 7 AL 14'!T23+'SEMANA DEL 14 AL 21 '!T21+'SEMANA DEL 21AL 28-3'!T22+#REF! -> #REF! | U16: =+'SEMANA DEL 2 AL 7-3-26'!U17+'SEMANA DEL 7 AL 14'!U23+'SEMANA DEL 14 AL 21 '!U21+'SEMANA DEL 21AL 28-3'!U22+#REF! -> #REF! | V16: =+'SEMANA DEL 2 AL 7-3-26'!V17+'SEMANA DEL 7 AL 14'!V23+'SEMANA DEL 14 AL 21 '!V21+'SEMANA DEL 21AL 28-3'!V22+#REF! -> #REF! | W16: =+'SEMANA DEL 2 AL 7-3-26'!W17+'SEMANA DEL 7 AL 14'!W23+'SEMANA DEL 14 AL 21 '!W21+'SEMANA DEL 21AL 28-3'!W22+#REF! -> #REF! | X16: =+'SEMANA DEL 2 AL 7-3-26'!X17+'SEMANA DEL 7 AL 14'!X23+'SEMANA DEL 14 AL 21 '!X21+'SEMANA DEL 21AL 28-3'!X22+#REF! -> #REF! | Y16: =+'SEMANA DEL 2 AL 7-3-26'!Y17+'SEMANA DEL 7 AL 14'!Y23+'SEMANA DEL 14 AL 21 '!Y21+'SEMANA DEL 21AL 28-3'!Y22+#REF! -> #REF! | ... AW16: =+'SEMANA DEL 2 AL 7-3-26'!AW17+'SEMANA DEL 7 AL 14'!AW23+'SEMANA DEL 14 AL 21 '!AW21+'SEMANA DEL 21AL 28-3'!AW22+#REF! -> #REF! | AX16: =+B16+R16-AH16 -> #REF! | AY16: =+C16+S16-AI16 -> #REF! | AZ16: =+D16+T16-AJ16 -> #REF! | BA16: =+E16+U16-AK16 -> #REF! | BB16: =+F16+V16-AL16 -> #REF! | BC16: =+G16+W16-AM16 -> #REF! | BD16: =+H16+X16-AN16 -> #REF! | BE16: =+I16+Y16-AO16 -> #REF! | ... BM16: =+Q16+AG16-AW16 -> #REF! | BN16: =+'SEMANA DEL 2 AL 7-3-26'!BN17+'SEMANA DEL 7 AL 14'!BN23+'SEMANA DEL 14 AL 21 '!BN21+'SEMANA DEL 21AL 28-3'!BN22+#REF! -> #REF! | BO16: =+'SEMANA DEL 2 AL 7-3-26'!BO17+'SEMANA DEL 7 AL 14'!BO23+'SEMANA DEL 14 AL 21 '!BO21+'SEMANA DEL 21AL 28-3'!BO22+#REF! -> #REF! | BP16: =+'SEMANA DEL 2 AL 7-3-26'!BP17+'SEMANA DEL 7 AL 14'!BP23+'SEMANA DEL 14 AL 21 '!BP21+'SEMANA DEL 21AL 28-3'!BP22+#REF! -> #REF! | BQ16: =+'SEMANA DEL 2 AL 7-3-26'!BQ17+'SEMANA DEL 7 AL 14'!BQ23+'SEMANA DEL 14 AL 21 '!BQ21+'SEMANA DEL 21AL 28-3'!BQ22+#REF! -> #REF! | BR16: =+'SEMANA DEL 2 AL 7-3-26'!BR17+'SEMANA DEL 7 AL 14'!BR23+'SEMANA DEL 14 AL 21 '!BR21+'SEMANA DEL 21AL 28-3'!BR22+#REF! -> #REF! | BS16: =+'SEMANA DEL 2 AL 7-3-26'!BS17+'SEMANA DEL 7 AL 14'!BS23+'SEMANA DEL 14 AL 21 '!BS21+'SEMANA DEL 21AL 28-3'!BS22+#REF! -> #REF! | BT16: =+'SEMANA DEL 2 AL 7-3-26'!BT17+'SEMANA DEL 7 AL 14'!BT23+'SEMANA DEL 14 AL 21 '!BT21+'SEMANA DEL 21AL 28-3'!BT22+#REF! -> #REF! | BU16: =+'SEMANA DEL 2 AL 7-3-26'!BU17+'SEMANA DEL 7 AL 14'!BU23+'SEMANA DEL 14 AL 21 '!BU21+'SEMANA DEL 21AL 28-3'!BU22+#REF! -> #REF! | ... CI16: =+'SEMANA DEL 2 AL 7-3-26'!CI17+'SEMANA DEL 7 AL 14'!CI23+'SEMANA DEL 14 AL 21 '!CI21+'SEMANA DEL 21AL 28-3'!CI22+#REF! -> #REF!
A17: =+'SEMANA DEL 2 AL 7-3-26'!A17 -> JOSE JURADO | B17: =+'SEMANA DEL 2 AL 7-3-26'!B17 -> 0 | C17: =+'SEMANA DEL 2 AL 7-3-26'!C17 -> 0 | D17: =+'SEMANA DEL 2 AL 7-3-26'!D17 -> 0 | E17: =+'SEMANA DEL 2 AL 7-3-26'!E17 -> 0 | F17: =+'SEMANA DEL 2 AL 7-3-26'!F17 -> 0 | G17: =+'SEMANA DEL 2 AL 7-3-26'!G17 -> 0 | H17: =+'SEMANA DEL 2 AL 7-3-26'!H17 -> 0 | ... Q17: =+'SEMANA DEL 2 AL 7-3-26'!Q17 -> 0 | R17: =+'SEMANA DEL 2 AL 7-3-26'!#REF!+'SEMANA DEL 7 AL 14'!R24+'SEMANA DEL 14 AL 21 '!R22+'SEMANA DEL 21AL 28-3'!R23+#REF! -> #REF! | S17: =+'SEMANA DEL 2 AL 7-3-26'!#REF!+'SEMANA DEL 7 AL 14'!S24+'SEMANA DEL 14 AL 21 '!S22+'SEMANA DEL 21AL 28-3'!S23+#REF! -> #REF! | T17: =+'SEMANA DEL 2 AL 7-3-26'!#REF!+'SEMANA DEL 7 AL 14'!T24+'SEMANA DEL 14 AL 21 '!T22+'SEMANA DEL 21AL 28-3'!T23+#REF! -> #REF! | U17: =+'SEMANA DEL 2 AL 7-3-26'!#REF!+'SEMANA DEL 7 AL 14'!U24+'SEMANA DEL 14 AL 21 '!U22+'SEMANA DEL 21AL 28-3'!U23+#REF! -> #REF! | V17: =+'SEMANA DEL 2 AL 7-3-26'!#REF!+'SEMANA DEL 7 AL 14'!V24+'SEMANA DEL 14 AL 21 '!V22+'SEMANA DEL 21AL 28-3'!V23+#REF! -> #REF! | W17: =+'SEMANA DEL 2 AL 7-3-26'!#REF!+'SEMANA DEL 7 AL 14'!W24+'SEMANA DEL 14 AL 21 '!W22+'SEMANA DEL 21AL 28-3'!W23+#REF! -> #REF! | X17: =+'SEMANA DEL 2 AL 7-3-26'!#REF!+'SEMANA DEL 7 AL 14'!X24+'SEMANA DEL 14 AL 21 '!X22+'SEMANA DEL 21AL 28-3'!X23+#REF! -> #REF! | Y17: =+'SEMANA DEL 2 AL 7-3-26'!#REF!+'SEMANA DEL 7 AL 14'!Y24+'SEMANA DEL 14 AL 21 '!Y22+'SEMANA DEL 21AL 28-3'!Y23+#REF! -> #REF! | ... AW17: =+'SEMANA DEL 2 AL 7-3-26'!#REF!+'SEMANA DEL 7 AL 14'!AW24+'SEMANA DEL 14 AL 21 '!AW22+'SEMANA DEL 21AL 28-3'!AW23+#REF! -> #REF! | AX17: =+B17+R17-AH17 -> #REF! | AY17: =+C17+S17-AI17 -> #REF! | AZ17: =+D17+T17-AJ17 -> #REF! | BA17: =+E17+U17-AK17 -> #REF! | BB17: =+F17+V17-AL17 -> #REF! | BC17: =+G17+W17-AM17 -> #REF! | BD17: =+H17+X17-AN17 -> #REF! | BE17: =+I17+Y17-AO17 -> #REF! | ... BM17: =+Q17+AG17-AW17 -> #REF! | BN17: =+'SEMANA DEL 2 AL 7-3-26'!#REF!+'SEMANA DEL 7 AL 14'!BN24+'SEMANA DEL 14 AL 21 '!BN22+'SEMANA DEL 21AL 28-3'!BN23+#REF! -> #REF! | BO17: =+'SEMANA DEL 2 AL 7-3-26'!#REF!+'SEMANA DEL 7 AL 14'!BO24+'SEMANA DEL 14 AL 21 '!BO22+'SEMANA DEL 21AL 28-3'!BO23+#REF! -> #REF! | BP17: =+'SEMANA DEL 2 AL 7-3-26'!#REF!+'SEMANA DEL 7 AL 14'!BP24+'SEMANA DEL 14 AL 21 '!BP22+'SEMANA DEL 21AL 28-3'!BP23+#REF! -> #REF! | BQ17: =+'SEMANA DEL 2 AL 7-3-26'!#REF!+'SEMANA DEL 7 AL 14'!BQ24+'SEMANA DEL 14 AL 21 '!BQ22+'SEMANA DEL 21AL 28-3'!BQ23+#REF! -> #REF! | BR17: =+'SEMANA DEL 2 AL 7-3-26'!#REF!+'SEMANA DEL 7 AL 14'!BR24+'SEMANA DEL 14 AL 21 '!BR22+'SEMANA DEL 21AL 28-3'!BR23+#REF! -> #REF! | BS17: =+'SEMANA DEL 2 AL 7-3-26'!#REF!+'SEMANA DEL 7 AL 14'!BS24+'SEMANA DEL 14 AL 21 '!BS22+'SEMANA DEL 21AL 28-3'!BS23+#REF! -> #REF! | BT17: =+'SEMANA DEL 2 AL 7-3-26'!#REF!+'SEMANA DEL 7 AL 14'!BT24+'SEMANA DEL 14 AL 21 '!BT22+'SEMANA DEL 21AL 28-3'!BT23+#REF! -> #REF! | BU17: =+'SEMANA DEL 2 AL 7-3-26'!#REF!+'SEMANA DEL 7 AL 14'!BU24+'SEMANA DEL 14 AL 21 '!BU22+'SEMANA DEL 21AL 28-3'!BU23+#REF! -> #REF! | ... CI17: =+'SEMANA DEL 2 AL 7-3-26'!#REF!+'SEMANA DEL 7 AL 14'!CI24+'SEMANA DEL 14 AL 21 '!CI22+'SEMANA DEL 21AL 28-3'!CI23+#REF! -> #REF!
